Workbook

Sheet Executive Dashboard
A1: Working Capital Distress - Executive Dashboard
A4: Asian Paints (Stable Co) · Berger Paints (Slippery Co) · Kansai Nerolac (Sinking Co) | FY23 – FY26, standalone financials, ₹ crore
A6: Where each company stands today (FY26)
B7: Companies | C7: Current Ratio | D7: Quick Ratio | E7: Cash Conversion Cycle (days) | F7: Interest Coverage (x) | G7: Liabilities / EBITDA (x) | H7: OCF / Curr. Liab. | I7: Altman Z | J7: Distress Classification
B8: Asian Paints | C8: =Indicators!C8 -> 2.4631067 | D8: =Indicators!D8 -> 1.7744366 | E8: =Indicators!K8 -> 74.862992 | F8: =Indicators!L8 -> 47.330035 | G8: =Indicators!M8 -> 1.3078209 | H8: =Indicators!N8 -> 0.96503794 | I8: =Indicators!O8 -> 17.53207 | J8: =Scorecard!J5 -> Healthy
B9: Berger Paints | C9: =Indicators!C12 -> 2.1849998 | D9: =Indicators!D12 -> 1.1460242 | E9: =Indicators!K12 -> 81.155519 | F9: =Indicators!L12 -> 33.636184 | G9: =Indicators!M12 -> 1.3851466 | H9: =Indicators!N12 -> 0.65656292 | I9: =Indicators!O12 -> 17.691482 | J9: =Scorecard!J6 -> Healthy
B10: Kansai Nerolac | C10: =Indicators!C16 -> 3.7476689 | D10: =Indicators!D16 -> 2.7511864 | E10: =Indicators!K16 -> 95.527349 | F10: =Indicators!L16 -> 49.827268 | G10: =Indicators!M16 -> 1.6183827 | H10: =Indicators!N16 -> 0.59094641 | I10: =Indicators!O16 -> 9.3749029 | J10: =Scorecard!J7 -> Healthy
A19: Four-year trajectory: the direction matters more than the level
A57: FY26 Distress Flags at a Glance
C58: Current Ratio | D58: Quick Ratio | E58: WC / Total Assets | F58: Interest Coverage | G58: Leverage (Liab/EBITDA) | H58: OCF / Curr. Liab. | I58: Altman Z (classic)
B59: Asian Paints | C59: =Scorecard!B5 -> ok | D59: =Scorecard!C5 -> ok | E59: =Scorecard!D5 -> ok | F59: =Scorecard!E5 -> ok | G59: =Scorecard!F5 -> ok | H59: =Scorecard!G5 -> ok | I59: =Scorecard!H5 -> ok
B60: Berger Paints | C60: =Scorecard!B6 -> ok | D60: =Scorecard!C6 -> ok | E60: =Scorecard!D6 -> ok | F60: =Scorecard!E6 -> ok | G60: =Scorecard!F6 -> ok | H60: =Scorecard!G6 -> ok | I60: =Scorecard!H6 -> ok
B61: Kansai Nerolac | C61: =Scorecard!B7 -> ok | D61: =Scorecard!C7 -> ok | E61: =Scorecard!D7 -> ok | F61: =Scorecard!E7 -> ok | G61: =Scorecard!F7 -> ok | H61: =Scorecard!G7 -> ok | I61: =Scorecard!H7 -> ok
B63: Legend: | C63: RED = breach | D63: amber = watch | E63: ok = healthy
A67: The Story Behind the Numbers
B69: Asian Paints
B70: Asian Paints funds itself comfortably: current and quick ratios have held above 2x and 1.3x for four years, operating cash flow covers current liabilities better each year, and the Altman Z score, while easing as new competition compresses margins, sits far inside safe territory. This is a balance sheet built for scale, not survival - the company can absorb a bad quarter without touching its working-capital cushion.
B75: Berger Paints
B76: Berger looks healthy on the surface - its current ratio has actually improved from 1.3x to 2.2x - but look closer at the cash conversion cycle: it has stretched from 66 days to 81 days over four years. Berger is collecting and stocking more slowly than it is paying suppliers. Liquidity is being held together by leaning on payables, not by faster cash generation. That is the 'slippery' pattern: comfortable ratios masking a working-capital cycle moving the wrong way.
B81: Kansai Nerolac
B82: Kansai Nerolac carries the weakest interest coverage and the lowest Altman Z of the three all four years, and its Z score has fallen from 14.3 to 9.4 even after a one-off gain lifted FY25 profits. Leverage against EBITDA has more than doubled since FY23. None of its flags are red yet - but every trend line among current ratio, interest cover and Altman Z is moving toward the danger zone faster than at the other two firms. This is what deterioration looks like before it becomes distress.
B87: Bottom line for the room
B88: None of these three companies would be flagged 'distressed' by a textbook threshold today - all three are large, well-capitalised, investment-grade businesses. But working-capital distress rarely announces itself with a single red number; it shows up first as a change in direction. Asian Paints is getting stronger. Berger is holding its ratios steady by stretching payables rather than collecting faster - worth a supplier-relationship conversation before it becomes a covenant conversation. Kansai Nerolac is the one to watch: its trend lines, not its current numbers, are the early-warning signal a credit committee would want flagged now, while there is still time to act on it.

Sheet Guide
A1: Working Capital Distress Model - Multi-Period
A2: Tracks each firm over 4 years. 'Inputs' → financials; 'Indicators' → ratios; 'Scorecard' → latest-year flags; 'Trend' → 4-year trajectory + charts.
A4: Distress indicators - what each one signals
A5: Indicator | B5: Formula | C5: Distress signal | D5: What it tells you
A6: Current ratio | B6: Curr. assets / Curr. liabilities | C6: < 1.0 (amber 1.0–1.5) | D6: Short-term solvency. Below 1 means current assets can't cover current dues.
A7: Quick ratio | B7: (Curr. assets − Inventory) / Curr. liab. | C7: < 0.7 (amber 0.7–1.0) | D7: Liquidity excluding slow-moving inventory.
A8: Net working capital | B8: Curr. assets − Curr. liabilities | C8: Negative | D8: Negative NWC = operations funded by short-term money - fragile.
A9: WC / Total assets | B9: (Curr. assets − Curr. liab.) / Total assets | C9: < 0 (amber 0–0.10) | D9: Altman's X1. Shrinking/negative = liquidity draining vs. size.
A10: DSO / DIO / DPO | B10: Recv, Inv, Pay ÷ (Sales or COGS) × 365 | C10: Rising trend | D10: Days cash is tied in receivables, inventory, payables.
A11: Cash conversion cycle | B11: DSO + DIO − DPO | C11: Rising | D11: Days cash is locked in operations. A low CCC from stretched payables is a warning, not a win.
A12: Interest coverage | B12: EBIT / Interest | C12: < 1.5 (amber 1.5–3) | D12: Can profit service debt? Below 1, EBIT can't cover interest.
A13: Liabilities / EBITDA | B13: Total liabilities / EBITDA | C13: > 4 or negative | D13: Leverage vs. cash earnings; high/negative = unsustainable debt.
A14: OCF / Curr. liab. | B14: Operating cash flow / Curr. liab. | C14: < 0 (amber 0–0.4) | D14: Does the business generate cash to meet obligations?
A15: Altman Z (classic) | B15: 1.2X1+1.4X2+3.3X3+0.6X4+1.0X5 | C15: < 1.81 distress; 1.81–2.99 grey | D15: Listed manufacturers. X4 uses MARKET value of equity.
A16: Altman Z″ (private) | B16: 6.56X1+3.26X2+6.72X3+1.05X4 | C16: < 1.1 distress; 1.1–2.6 grey | D16: Private / non-manufacturing firms. X4 uses BOOK equity; no sales term.
A18: Which Altman to use: | B18: Classic Z for LISTED firms (needs market cap). Z″ for PRIVATE / unlisted firms (book value only). When the two disagree, weight the trend and the flag score.
A19: Distress score: | B19: Red flag = 1, amber = 0.5. Score ≥5 = Distress, 2.5–4.9 = Watch, < 2.5 = Healthy.
A20: Trend verdict: | B20: Compares FY26 vs FY23. Counts adverse moves (current ratio down, CCC up, OCF down, Z down). ≥3 = Deteriorating.

Sheet Inputs
A1: Firm Inputs (4 years each)
A2: Blue = input (₹ crore, standalone financials). Stable Co = Asian Paints, Slippery Co = Berger Paints, Sinking Co = Kansai Nerolac. Ret. earn. = Other Equity (proxy; Ind AS does not separately disclose retained earnings). Mkt val eq. = indicative FY-end market capitalisation (shares outstanding x approx. closing price); treat as illustrative for Altman Z (classic) only - Z″ (book-value based, in col P of Indicators) is the more reliable cross-company read per the Guide sheet.
A4: Firm | B4: Year | C4: Curr.assets | D4: Cash | E4: Inventory | F4: Receivables | G4: Curr.liab. | H4: Payables | I4: Total assets | J4: Total liab. | K4: Ret. earn. | L4: Sales | M4: COGS | N4: EBIT | O4: EBITDA | P4: Interest | Q4: Op cash flow | R4: Mkt val eq.
A5: Asian Paints | B5: FY23 | C5: 13875.73 | D5: 156.44 | E5: 5321.79 | F5: 3462.61 | G5: 5831.46 | H5: 3045.86 | I5: 22529.84 | J5: 6944.28 | K5: 15489.64 | L5: 30078.4 | M5: 18327.54 | N5: 5582.66 | O5: 6338.49 | P5: 93.06 | Q5: 4221.65 | R5: 253820
A6: Asian Paints | B6: FY24 | C6: 14553.21 | D6: 325.96 | E6: 5074.76 | F6: 3633.45 | G6: 6221.01 | H6: 3238.83 | I6: 25981.9 | J6: 7556.81 | K6: 18329.17 | L6: 30850.12 | M6: 17219.39 | N6: 7120.46 | O6: 7854.95 | P6: 115.42 | Q6: 5737.84 | R6: 276404
A7: Asian Paints | B7: FY25 | C7: 14341.94 | D7: 178.41 | E7: 5848.23 | F7: 3197.55 | G7: 6234.29 | H7: 3123.69 | I7: 26675.48 | J7: 7687.73 | K7: 18891.83 | L7: 29552.65 | M7: 16791.84 | N7: 5425 | O7: 6326.85 | P7: 143.77 | Q7: 4124.02 | R7: 220616
A8: Asian Paints | B8: FY26 | C8: 17256.23 | D8: 395.38 | E8: 4824.74 | F8: 3227.71 | G8: 7005.88 | H8: 3114.48 | I8: 30084.26 | J8: 9302.7 | K8: 20685.64 | L8: 30769.48 | M8: 17067.72 | N8: 6027.48 | O8: 7113.13 | P8: 127.35 | Q8: 6760.94 | R8: 224453
A9: Berger Paints | B9: FY23 | C9: 3600.21 | D9: 56.87 | E9: 2146.1 | F9: 970.8 | G9: 2696.03 | H9: 1674.34 | I9: 7400.09 | J9: 3104.9 | K9: 4198.05 | L9: 9470.62 | M9: 6087.12 | N9: 1189 | O9: 1423 | P9: 86.28 | Q9: 934.29 | R9: 63141
A10: Berger Paints | B10: FY24 | C10: 3623.87 | D10: 151.2 | E10: 2019.43 | F10: 979.39 | G10: 2036.27 | H10: 1567.19 | I10: 7581.66 | J10: 2576.42 | K10: 4888.66 | L10: 10002.93 | M10: 6003.31 | N10: 1432.12 | O10: 1729.11 | P10: 64.66 | Q10: 1482.9 | R10: 58873
A11: Berger Paints | B11: FY25 | C11: 4133.8 | D11: 141.39 | E11: 2206.6 | F11: 1124.37 | G11: 1985.76 | H11: 1569.34 | I11: 8176.51 | J11: 2495.45 | K11: 5564.47 | L11: 10169.22 | M11: 6088.59 | N11: 1478.6 | O11: 1796.35 | P11: 47.86 | Q11: 1118.83 | R11: 55963
A12: Berger Paints | B12: FY26 | C12: 4680.51 | D12: 151.94 | E12: 2225.6 | F12: 1129.27 | G12: 2142.11 | H12: 1522.26 | I12: 8946.2 | J12: 2603.3 | K12: 6226.3 | L12: 10420.1 | M12: 6171.29 | N12: 1533.81 | O12: 1879.44 | P12: 45.6 | Q12: 1406.43 | R12: 63547
A13: Kansai Nerolac | B13: FY23 | C13: 3562.07 | D13: 90.22 | E13: 1648.02 | F13: 1117.15 | G13: 1250.59 | H13: 937.51 | I13: 6075.13 | J13: 1467.75 | K13: 4553.49 | L13: 7081.02 | M13: 4955.34 | N13: 660.09 | O13: 824.72 | P13: 9.73 | Q13: 386.19 | R13: 27486
A14: Kansai Nerolac | B14: FY24 | C14: 4578.1 | D14: 162.37 | E14: 1616.04 | F14: 1215.25 | G14: 1314.51 | H14: 1024.24 | I14: 7224.8 | J14: 1571.68 | K14: 5572.28 | L14: 7393.3 | M14: 4769.73 | N14: 936.03 | O14: 1115.99 | P14: 12.46 | Q14: 895.09 | R14: 24656
A15: Kansai Nerolac | B15: FY25 | C15: 5173.76 | D15: 85.72 | E15: 1609.71 | F15: 1274.7 | G15: 1287.33 | H15: 1023.65 | I15: 7969.24 | J15: 1603.01 | K15: 6285.39 | L15: 7496.71 | M15: 4852.61 | N15: 922.51 | O15: 1116.19 | P15: 15.09 | Q15: 647.48 | R15: 18189
A16: Kansai Nerolac | B16: FY26 | C16: 5614.72 | D16: 184.12 | E16: 1492.92 | F16: 1379.83 | G16: 1498.19 | H16: 1075.42 | I16: 8538.59 | J16: 1842.82 | K16: 6614.9 | L16: 7739.23 | M16: 5004.29 | N16: 917.32 | O16: 1138.68 | P16: 18.41 | Q16: 885.35 | R16: 19813
A18: Source: Standalone Balance Sheet, Statement of P&L and Cash Flow Statement in each company's audited Annual Report (FY22-23 through FY25-26 filings). COGS = Cost of materials consumed + Purchases of stock-in-trade + Changes in inventories. EBIT = Profit before tax + Finance costs (pre-exceptional items where disclosed). Sales = Revenue from operations (excl. other income).

Sheet Indicators
A1: Computed Indicators
A2: Formulas reference 'Inputs'. Ratios unitless; DSO/DIO/DPO/CCC in days; two Altman scores at right.
A4: Firm | B4: Year | C4: Current | D4: Quick | E4: Cash | F4: NWC | G4: WC/TA | H4: DSO | I4: DIO | J4: DPO | K4: CCC | L4: Int cov | M4: Liab/EBITDA | N4: OCF/CL | O4: Altman Z | P4: Altman Z″
A5: =Inputs!A5 -> Asian Paints | B5: =Inputs!B5 -> FY23 | C5: =IFERROR(Inputs!C5/Inputs!G5,"") -> 2.3794607 | D5: =IFERROR((Inputs!C5-Inputs!E5)/Inputs!G5,"") -> 1.4668608 | E5: =IFERROR(Inputs!D5/Inputs!G5,"") -> 0.026826901 | F5: =Inputs!C5-Inputs!G5 -> 8044.27 | G5: =IFERROR((Inputs!C5-Inputs!G5)/Inputs!I5,"") -> 0.35704958 | H5: =IFERROR(Inputs!F5/Inputs!L5*365,"") -> 42.018613 | I5: =IFERROR(Inputs!E5/Inputs!M5*365,"") -> 105.98549 | J5: =IFERROR(Inputs!H5/Inputs!M5*365,"") -> 60.659472 | K5: =H5+I5-J5 -> 87.344633 | L5: =IFERROR(Inputs!N5/Inputs!P5,"") -> 59.989899 | M5: =IFERROR(Inputs!J5/Inputs!O5,"") -> 1.0955732 | N5: =IFERROR(Inputs!Q5/Inputs!G5,"") -> 0.72394392 | O5: =IFERROR(1.2*(Inputs!C5-Inputs!G5)/Inputs!I5+1.4*Inputs!K5/Inputs!I5+3.3*Inputs!N5/Inputs!I5+0.6*Inputs!R5/Inputs!J5+1*Inputs!L5/Inputs!I5,"") -> 25.474303 | P5: =IFERROR(6.56*(Inputs!C5-Inputs!G5)/Inputs!I5+3.26*Inputs!K5/Inputs!I5+6.72*Inputs!N5/Inputs!I5+1.05*(Inputs!I5-Inputs!J5)/Inputs!J5,"") -> 8.6052881
A6: =Inputs!A6 -> Asian Paints | B6: =Inputs!B6 -> FY24 | C6: =IFERROR(Inputs!C6/Inputs!G6,"") -> 2.3393645 | D6: =IFERROR((Inputs!C6-Inputs!E6)/Inputs!G6,"") -> 1.5236192 | E6: =IFERROR(Inputs!D6/Inputs!G6,"") -> 0.052396637 | F6: =Inputs!C6-Inputs!G6 -> 8332.2 | G6: =IFERROR((Inputs!C6-Inputs!G6)/Inputs!I6,"") -> 0.32069248 | H6: =IFERROR(Inputs!F6/Inputs!L6*365,"") -> 42.988787 | I6: =IFERROR(Inputs!E6/Inputs!M6*365,"") -> 107.56986 | J6: =IFERROR(Inputs!H6/Inputs!M6*365,"") -> 68.653591 | K6: =H6+I6-J6 -> 81.905059 | L6: =IFERROR(Inputs!N6/Inputs!P6,"") -> 61.691735 | M6: =IFERROR(Inputs!J6/Inputs!O6,"") -> 0.96204432 | N6: =IFERROR(Inputs!Q6/Inputs!G6,"") -> 0.92233255 | O6: =IFERROR(1.2*(Inputs!C6-Inputs!G6)/Inputs!I6+1.4*Inputs!K6/Inputs!I6+3.3*Inputs!N6/Inputs!I6+0.6*Inputs!R6/Inputs!J6+1*Inputs!L6/Inputs!I6,"") -> 25.41031 | P6: =IFERROR(6.56*(Inputs!C6-Inputs!G6)/Inputs!I6+3.26*Inputs!K6/Inputs!I6+6.72*Inputs!N6/Inputs!I6+1.05*(Inputs!I6-Inputs!J6)/Inputs!J6,"") -> 8.8053073
A7: =Inputs!A7 -> Asian Paints | B7: =Inputs!B7 -> FY25 | C7: =IFERROR(Inputs!C7/Inputs!G7,"") -> 2.3004929 | D7: =IFERROR((Inputs!C7-Inputs!E7)/Inputs!G7,"") -> 1.3624182 | E7: =IFERROR(Inputs!D7/Inputs!G7,"") -> 0.028617533 | F7: =Inputs!C7-Inputs!G7 -> 8107.65 | G7: =IFERROR((Inputs!C7-Inputs!G7)/Inputs!I7,"") -> 0.30393642 | H7: =IFERROR(Inputs!F7/Inputs!L7*365,"") -> 39.492423 | I7: =IFERROR(Inputs!E7/Inputs!M7*365,"") -> 127.1215 | J7: =IFERROR(Inputs!H7/Inputs!M7*365,"") -> 67.898863 | K7: =H7+I7-J7 -> 98.715063 | L7: =IFERROR(Inputs!N7/Inputs!P7,"") -> 37.73388 | M7: =IFERROR(Inputs!J7/Inputs!O7,"") -> 1.215096 | N7: =IFERROR(Inputs!Q7/Inputs!G7,"") -> 0.66150596 | O7: =IFERROR(1.2*(Inputs!C7-Inputs!G7)/Inputs!I7+1.4*Inputs!K7/Inputs!I7+3.3*Inputs!N7/Inputs!I7+0.6*Inputs!R7/Inputs!J7+1*Inputs!L7/Inputs!I7,"") -> 20.353492 | P7: =IFERROR(6.56*(Inputs!C7-Inputs!G7)/Inputs!I7+3.26*Inputs!K7/Inputs!I7+6.72*Inputs!N7/Inputs!I7+1.05*(Inputs!I7-Inputs!J7)/Inputs!J7,"") -> 8.2626056
A8: =Inputs!A8 -> Asian Paints | B8: =Inputs!B8 -> FY26 | C8: =IFERROR(Inputs!C8/Inputs!G8,"") -> 2.4631067 | D8: =IFERROR((Inputs!C8-Inputs!E8)/Inputs!G8,"") -> 1.7744366 | E8: =IFERROR(Inputs!D8/Inputs!G8,"") -> 0.056435451 | F8: =Inputs!C8-Inputs!G8 -> 10250.35 | G8: =IFERROR((Inputs!C8-Inputs!G8)/Inputs!I8,"") -> 0.34072136 | H8: =IFERROR(Inputs!F8/Inputs!L8*365,"") -> 38.2884 | I8: =IFERROR(Inputs!E8/Inputs!M8*365,"") -> 103.17899 | J8: =IFERROR(Inputs!H8/Inputs!M8*365,"") -> 66.604397 | K8: =H8+I8-J8 -> 74.862992 | L8: =IFERROR(Inputs!N8/Inputs!P8,"") -> 47.330035 | M8: =IFERROR(Inputs!J8/Inputs!O8,"") -> 1.3078209 | N8: =IFERROR(Inputs!Q8/Inputs!G8,"") -> 0.96503794 | O8: =IFERROR(1.2*(Inputs!C8-Inputs!G8)/Inputs!I8+1.4*Inputs!K8/Inputs!I8+3.3*Inputs!N8/Inputs!I8+0.6*Inputs!R8/Inputs!J8+1*Inputs!L8/Inputs!I8,"") -> 17.53207 | P8: =IFERROR(6.56*(Inputs!C8-Inputs!G8)/Inputs!I8+3.26*Inputs!K8/Inputs!I8+6.72*Inputs!N8/Inputs!I8+1.05*(Inputs!I8-Inputs!J8)/Inputs!J8,"") -> 8.1686741
A9: =Inputs!A9 -> Berger Paints | B9: =Inputs!B9 -> FY23 | C9: =IFERROR(Inputs!C9/Inputs!G9,"") -> 1.3353746 | D9: =IFERROR((Inputs!C9-Inputs!E9)/Inputs!G9,"") -> 0.53935231 | E9: =IFERROR(Inputs!D9/Inputs!G9,"") -> 0.021093979 | F9: =Inputs!C9-Inputs!G9 -> 904.18 | G9: =IFERROR((Inputs!C9-Inputs!G9)/Inputs!I9,"") -> 0.122185 | H9: =IFERROR(Inputs!F9/Inputs!L9*365,"") -> 37.414868 | I9: =IFERROR(Inputs!E9/Inputs!M9*365,"") -> 128.6859 | J9: =IFERROR(Inputs!H9/Inputs!M9*365,"") -> 100.39791 | K9: =H9+I9-J9 -> 65.70286 | L9: =IFERROR(Inputs!N9/Inputs!P9,"") -> 13.780714 | M9: =IFERROR(Inputs!J9/Inputs!O9,"") -> 2.1819396 | N9: =IFERROR(Inputs!Q9/Inputs!G9,"") -> 0.34654288 | O9: =IFERROR(1.2*(Inputs!C9-Inputs!G9)/Inputs!I9+1.4*Inputs!K9/Inputs!I9+3.3*Inputs!N9/Inputs!I9+0.6*Inputs!R9/Inputs!J9+1*Inputs!L9/Inputs!I9,"") -> 14.952412 | P9: =IFERROR(6.56*(Inputs!C9-Inputs!G9)/Inputs!I9+3.26*Inputs!K9/Inputs!I9+6.72*Inputs!N9/Inputs!I9+1.05*(Inputs!I9-Inputs!J9)/Inputs!J9,"") -> 5.1831762
A10: =Inputs!A10 -> Berger Paints | B10: =Inputs!B10 -> FY24 | C10: =IFERROR(Inputs!C10/Inputs!G10,"") -> 1.7796608 | D10: =IFERROR((Inputs!C10-Inputs!E10)/Inputs!G10,"") -> 0.78793087 | E10: =IFERROR(Inputs!D10/Inputs!G10,"") -> 0.074253414 | F10: =Inputs!C10-Inputs!G10 -> 1587.6 | G10: =IFERROR((Inputs!C10-Inputs!G10)/Inputs!I10,"") -> 0.20940005 | H10: =IFERROR(Inputs!F10/Inputs!L10*365,"") -> 35.737264 | I10: =IFERROR(Inputs!E10/Inputs!M10*365,"") -> 122.78092 | J10: =IFERROR(Inputs!H10/Inputs!M10*365,"") -> 95.284826 | K10: =H10+I10-J10 -> 63.233362 | L10: =IFERROR(Inputs!N10/Inputs!P10,"") -> 22.148469 | M10: =IFERROR(Inputs!J10/Inputs!O10,"") -> 1.4900267 | N10: =IFERROR(Inputs!Q10/Inputs!G10,"") -> 0.72824331 | O10: =IFERROR(1.2*(Inputs!C10-Inputs!G10)/Inputs!I10+1.4*Inputs!K10/Inputs!I10+3.3*Inputs!N10/Inputs!I10+0.6*Inputs!R10/Inputs!J10+1*Inputs!L10/Inputs!I10,"") -> 16.807126 | P10: =IFERROR(6.56*(Inputs!C10-Inputs!G10)/Inputs!I10+3.26*Inputs!K10/Inputs!I10+6.72*Inputs!N10/Inputs!I10+1.05*(Inputs!I10-Inputs!J10)/Inputs!J10,"") -> 6.7849203
A11: =Inputs!A11 -> Berger Paints | B11: =Inputs!B11 -> FY25 | C11: =IFERROR(Inputs!C11/Inputs!G11,"") -> 2.0817219 | D11: =IFERROR((Inputs!C11-Inputs!E11)/Inputs!G11,"") -> 0.97051003 | E11: =IFERROR(Inputs!D11/Inputs!G11,"") -> 0.071201958 | F11: =Inputs!C11-Inputs!G11 -> 2148.04 | G11: =IFERROR((Inputs!C11-Inputs!G11)/Inputs!I11,"") -> 0.26270866 | H11: =IFERROR(Inputs!F11/Inputs!L11*365,"") -> 40.356591 | I11: =IFERROR(Inputs!E11/Inputs!M11*365,"") -> 132.28169 | J11: =IFERROR(Inputs!H11/Inputs!M11*365,"") -> 94.079105 | K11: =H11+I11-J11 -> 78.55918 | L11: =IFERROR(Inputs!N11/Inputs!P11,"") -> 30.894275 | M11: =IFERROR(Inputs!J11/Inputs!O11,"") -> 1.3891781 | N11: =IFERROR(Inputs!Q11/Inputs!G11,"") -> 0.5634266 | O11: =IFERROR(1.2*(Inputs!C11-Inputs!G11)/Inputs!I11+1.4*Inputs!K11/Inputs!I11+3.3*Inputs!N11/Inputs!I11+0.6*Inputs!R11/Inputs!J11+1*Inputs!L11/Inputs!I11,"") -> 16.564088 | P11: =IFERROR(6.56*(Inputs!C11-Inputs!G11)/Inputs!I11+3.26*Inputs!K11/Inputs!I11+6.72*Inputs!N11/Inputs!I11+1.05*(Inputs!I11-Inputs!J11)/Inputs!J11,"") -> 7.5475479
A12: =Inputs!A12 -> Berger Paints | B12: =Inputs!B12 -> FY26 | C12: =IFERROR(Inputs!C12/Inputs!G12,"") -> 2.1849998 | D12: =IFERROR((Inputs!C12-Inputs!E12)/Inputs!G12,"") -> 1.1460242 | E12: =IFERROR(Inputs!D12/Inputs!G12,"") -> 0.070930064 | F12: =Inputs!C12-Inputs!G12 -> 2538.4 | G12: =IFERROR((Inputs!C12-Inputs!G12)/Inputs!I12,"") -> 0.28374058 | H12: =IFERROR(Inputs!F12/Inputs!L12*365,"") -> 39.556583 | I12: =IFERROR(Inputs!E12/Inputs!M12*365,"") -> 131.63277 | J12: =IFERROR(Inputs!H12/Inputs!M12*365,"") -> 90.033834 | K12: =H12+I12-J12 -> 81.155519 | L12: =IFERROR(Inputs!N12/Inputs!P12,"") -> 33.636184 | M12: =IFERROR(Inputs!J12/Inputs!O12,"") -> 1.3851466 | N12: =IFERROR(Inputs!Q12/Inputs!G12,"") -> 0.65656292 | O12: =IFERROR(1.2*(Inputs!C12-Inputs!G12)/Inputs!I12+1.4*Inputs!K12/Inputs!I12+3.3*Inputs!N12/Inputs!I12+0.6*Inputs!R12/Inputs!J12+1*Inputs!L12/Inputs!I12,"") -> 17.691482 | P12: =IFERROR(6.56*(Inputs!C12-Inputs!G12)/Inputs!I12+3.26*Inputs!K12/Inputs!I12+6.72*Inputs!N12/Inputs!I12+1.05*(Inputs!I12-Inputs!J12)/Inputs!J12,"") -> 7.8406459
A13: =Inputs!A13 -> Kansai Nerolac | B13: =Inputs!B13 -> FY23 | C13: =IFERROR(Inputs!C13/Inputs!G13,"") -> 2.8483116 | D13: =IFERROR((Inputs!C13-Inputs!E13)/Inputs!G13,"") -> 1.5305176 | E13: =IFERROR(Inputs!D13/Inputs!G13,"") -> 0.072141949 | F13: =Inputs!C13-Inputs!G13 -> 2311.48 | G13: =IFERROR((Inputs!C13-Inputs!G13)/Inputs!I13,"") -> 0.38048239 | H13: =IFERROR(Inputs!F13/Inputs!L13*365,"") -> 57.584889 | I13: =IFERROR(Inputs!E13/Inputs!M13*365,"") -> 121.38971 | J13: =IFERROR(Inputs!H13/Inputs!M13*365,"") -> 69.05503 | K13: =H13+I13-J13 -> 109.91957 | L13: =IFERROR(Inputs!N13/Inputs!P13,"") -> 67.840699 | M13: =IFERROR(Inputs!J13/Inputs!O13,"") -> 1.7796949 | N13: =IFERROR(Inputs!Q13/Inputs!G13,"") -> 0.30880624 | O13: =IFERROR(1.2*(Inputs!C13-Inputs!G13)/Inputs!I13+1.4*Inputs!K13/Inputs!I13+3.3*Inputs!N13/Inputs!I13+0.6*Inputs!R13/Inputs!J13+1*Inputs!L13/Inputs!I13,"") -> 14.266029 | P13: =IFERROR(6.56*(Inputs!C13-Inputs!G13)/Inputs!I13+3.26*Inputs!K13/Inputs!I13+6.72*Inputs!N13/Inputs!I13+1.05*(Inputs!I13-Inputs!J13)/Inputs!J13,"") -> 8.9656198
A14: =Inputs!A14 -> Kansai Nerolac | B14: =Inputs!B14 -> FY24 | C14: =IFERROR(Inputs!C14/Inputs!G14,"") -> 3.4827426 | D14: =IFERROR((Inputs!C14-Inputs!E14)/Inputs!G14,"") -> 2.2533568 | E14: =IFERROR(Inputs!D14/Inputs!G14,"") -> 0.12352131 | F14: =Inputs!C14-Inputs!G14 -> 3263.59 | G14: =IFERROR((Inputs!C14-Inputs!G14)/Inputs!I14,"") -> 0.45172046 | H14: =IFERROR(Inputs!F14/Inputs!L14*365,"") -> 59.995706 | I14: =IFERROR(Inputs!E14/Inputs!M14*365,"") -> 123.66625 | J14: =IFERROR(Inputs!H14/Inputs!M14*365,"") -> 78.379195 | K14: =H14+I14-J14 -> 105.28276 | L14: =IFERROR(Inputs!N14/Inputs!P14,"") -> 75.122793 | M14: =IFERROR(Inputs!J14/Inputs!O14,"") -> 1.408328 | N14: =IFERROR(Inputs!Q14/Inputs!G14,"") -> 0.68093054 | O14: =IFERROR(1.2*(Inputs!C14-Inputs!G14)/Inputs!I14+1.4*Inputs!K14/Inputs!I14+3.3*Inputs!N14/Inputs!I14+0.6*Inputs!R14/Inputs!J14+1*Inputs!L14/Inputs!I14,"") -> 12.485311 | P14: =IFERROR(6.56*(Inputs!C14-Inputs!G14)/Inputs!I14+3.26*Inputs!K14/Inputs!I14+6.72*Inputs!N14/Inputs!I14+1.05*(Inputs!I14-Inputs!J14)/Inputs!J14,"") -> 10.124967
A15: =Inputs!A15 -> Kansai Nerolac | B15: =Inputs!B15 -> FY25 | C15: =IFERROR(Inputs!C15/Inputs!G15,"") -> 4.018985 | D15: =IFERROR((Inputs!C15-Inputs!E15)/Inputs!G15,"") -> 2.7685597 | E15: =IFERROR(Inputs!D15/Inputs!G15,"") -> 0.066587433 | F15: =Inputs!C15-Inputs!G15 -> 3886.43 | G15: =IFERROR((Inputs!C15-Inputs!G15)/Inputs!I15,"") -> 0.48767888 | H15: =IFERROR(Inputs!F15/Inputs!L15*365,"") -> 62.062625 | I15: =IFERROR(Inputs!E15/Inputs!M15*365,"") -> 121.07797 | J15: =IFERROR(Inputs!H15/Inputs!M15*365,"") -> 76.996142 | K15: =H15+I15-J15 -> 106.14445 | L15: =IFERROR(Inputs!N15/Inputs!P15,"") -> 61.133863 | M15: =IFERROR(Inputs!J15/Inputs!O15,"") -> 1.4361444 | N15: =IFERROR(Inputs!Q15/Inputs!G15,"") -> 0.5029635 | O15: =IFERROR(1.2*(Inputs!C15-Inputs!G15)/Inputs!I15+1.4*Inputs!K15/Inputs!I15+3.3*Inputs!N15/Inputs!I15+0.6*Inputs!R15/Inputs!J15+1*Inputs!L15/Inputs!I15,"") -> 9.8201808 | P15: =IFERROR(6.56*(Inputs!C15-Inputs!G15)/Inputs!I15+3.26*Inputs!K15/Inputs!I15+6.72*Inputs!N15/Inputs!I15+1.05*(Inputs!I15-Inputs!J15)/Inputs!J15,"") -> 10.718249
A16: =Inputs!A16 -> Kansai Nerolac | B16: =Inputs!B16 -> FY26 | C16: =IFERROR(Inputs!C16/Inputs!G16,"") -> 3.7476689 | D16: =IFERROR((Inputs!C16-Inputs!E16)/Inputs!G16,"") -> 2.7511864 | E16: =IFERROR(Inputs!D16/Inputs!G16,"") -> 0.12289496 | F16: =Inputs!C16-Inputs!G16 -> 4116.53 | G16: =IFERROR((Inputs!C16-Inputs!G16)/Inputs!I16,"") -> 0.48210887 | H16: =IFERROR(Inputs!F16/Inputs!L16*365,"") -> 65.075977 | I16: =IFERROR(Inputs!E16/Inputs!M16*365,"") -> 108.88973 | J16: =IFERROR(Inputs!H16/Inputs!M16*365,"") -> 78.43836 | K16: =H16+I16-J16 -> 95.527349 | L16: =IFERROR(Inputs!N16/Inputs!P16,"") -> 49.827268 | M16: =IFERROR(Inputs!J16/Inputs!O16,"") -> 1.6183827 | N16: =IFERROR(Inputs!Q16/Inputs!G16,"") -> 0.59094641 | O16: =IFERROR(1.2*(Inputs!C16-Inputs!G16)/Inputs!I16+1.4*Inputs!K16/Inputs!I16+3.3*Inputs!N16/Inputs!I16+0.6*Inputs!R16/Inputs!J16+1*Inputs!L16/Inputs!I16,"") -> 9.3749029 | P16: =IFERROR(6.56*(Inputs!C16-Inputs!G16)/Inputs!I16+3.26*Inputs!K16/Inputs!I16+6.72*Inputs!N16/Inputs!I16+1.05*(Inputs!I16-Inputs!J16)/Inputs!J16,"") -> 10.22523

Sheet Scorecard
A1: Distress Scorecard (latest year)
A2: Latest-year flags drive the score and classification. Both Altman variants shown - use Z″ for private firms.
A4: Firm | B4: Current | C4: Quick | D4: WC/TA | E4: Int cov | F4: Leverage | G4: OCF/CL | H4: Altman | I4: Score | J4: Classification | K4: Altman Z | L4: Z zone | M4: Altman Z″ | N4: Z″ zone
A5: =Indicators!A8 -> Asian Paints | B5: =IF(Indicators!C8="","",IF(Indicators!C8<1,"RED",IF(Indicators!C8<1.5,"amber","ok"))) -> ok | C5: =IF(Indicators!D8="","",IF(Indicators!D8<0.7,"RED",IF(Indicators!D8<1,"amber","ok"))) -> ok | D5: =IF(Indicators!G8="","",IF(Indicators!G8<0,"RED",IF(Indicators!G8<0.1,"amber","ok"))) -> ok | E5: =IF(Indicators!L8="","",IF(Indicators!L8<1.5,"RED",IF(Indicators!L8<3,"amber","ok"))) -> ok | F5: =IF(Indicators!M8="","",IF(OR(Indicators!M8<0,Indicators!M8>4),"RED",IF(Indicators!M8>3,"amber","ok"))) -> ok | G5: =IF(Indicators!N8="","",IF(Indicators!N8<0,"RED",IF(Indicators!N8<0.4,"amber","ok"))) -> ok | H5: =IF(Indicators!O8="","",IF(Indicators!O8<1.81,"RED",IF(Indicators!O8<2.99,"amber","ok"))) -> ok | I5: =COUNTIF(B5:H5,"RED")+COUNTIF(B5:H5,"amber")*0.5 -> 0 | J5: =IF(I5>=5,"Distress",IF(I5>=2.5,"Watch","Healthy")) -> Healthy | K5: =Indicators!O8 -> 17.53207 | L5: =IF(K5<1.81,"Distress",IF(K5<2.99,"Grey","Safe")) -> Safe | M5: =Indicators!P8 -> 8.1686741 | N5: =IF(M5<1.1,"Distress",IF(M5<2.6,"Grey","Safe")) -> Safe
A6: =Indicators!A12 -> Berger Paints | B6: =IF(Indicators!C12="","",IF(Indicators!C12<1,"RED",IF(Indicators!C12<1.5,"amber","ok"))) -> ok | C6: =IF(Indicators!D12="","",IF(Indicators!D12<0.7,"RED",IF(Indicators!D12<1,"amber","ok"))) -> ok | D6: =IF(Indicators!G12="","",IF(Indicators!G12<0,"RED",IF(Indicators!G12<0.1,"amber","ok"))) -> ok | E6: =IF(Indicators!L12="","",IF(Indicators!L12<1.5,"RED",IF(Indicators!L12<3,"amber","ok"))) -> ok | F6: =IF(Indicators!M12="","",IF(OR(Indicators!M12<0,Indicators!M12>4),"RED",IF(Indicators!M12>3,"amber","ok"))) -> ok | G6: =IF(Indicators!N12="","",IF(Indicators!N12<0,"RED",IF(Indicators!N12<0.4,"amber","ok"))) -> ok | H6: =IF(Indicators!O12="","",IF(Indicators!O12<1.81,"RED",IF(Indicators!O12<2.99,"amber","ok"))) -> ok | I6: =COUNTIF(B6:H6,"RED")+COUNTIF(B6:H6,"amber")*0.5 -> 0 | J6: =IF(I6>=5,"Distress",IF(I6>=2.5,"Watch","Healthy")) -> Healthy | K6: =Indicators!O12 -> 17.691482 | L6: =IF(K6<1.81,"Distress",IF(K6<2.99,"Grey","Safe")) -> Safe | M6: =Indicators!P12 -> 7.8406459 | N6: =IF(M6<1.1,"Distress",IF(M6<2.6,"Grey","Safe")) -> Safe
A7: =Indicators!A16 -> Kansai Nerolac | B7: =IF(Indicators!C16="","",IF(Indicators!C16<1,"RED",IF(Indicators!C16<1.5,"amber","ok"))) -> ok | C7: =IF(Indicators!D16="","",IF(Indicators!D16<0.7,"RED",IF(Indicators!D16<1,"amber","ok"))) -> ok | D7: =IF(Indicators!G16="","",IF(Indicators!G16<0,"RED",IF(Indicators!G16<0.1,"amber","ok"))) -> ok | E7: =IF(Indicators!L16="","",IF(Indicators!L16<1.5,"RED",IF(Indicators!L16<3,"amber","ok"))) -> ok | F7: =IF(Indicators!M16="","",IF(OR(Indicators!M16<0,Indicators!M16>4),"RED",IF(Indicators!M16>3,"amber","ok"))) -> ok | G7: =IF(Indicators!N16="","",IF(Indicators!N16<0,"RED",IF(Indicators!N16<0.4,"amber","ok"))) -> ok | H7: =IF(Indicators!O16="","",IF(Indicators!O16<1.81,"RED",IF(Indicators!O16<2.99,"amber","ok"))) -> ok | I7: =COUNTIF(B7:H7,"RED")+COUNTIF(B7:H7,"amber")*0.5 -> 0 | J7: =IF(I7>=5,"Distress",IF(I7>=2.5,"Watch","Healthy")) -> Healthy | K7: =Indicators!O16 -> 9.3749029 | L7: =IF(K7<1.81,"Distress",IF(K7<2.99,"Grey","Safe")) -> Safe | M7: =Indicators!P16 -> 10.22523 | N7: =IF(M7<1.1,"Distress",IF(M7<2.6,"Grey","Safe")) -> Safe
A9: Red flags across a row name exactly which working-capital indicators drove the classification.

Sheet Trend
A1: 4-Year Trend (FY23 → FY26)
A2: Deterioration - not a single bad year - is the strongest distress signal. Direction columns compare latest vs earliest.
A4: Firm | B4: CR FY23 | C4: CR FY26 | D4: CR dir | E4: Z FY23 | F4: Z FY26 | G4: Z dir | H4: CCC FY23 | I4: CCC FY26 | J4: CCC dir | K4: OCF/CL FY23 | L4: OCF/CL FY26 | M4: OCF dir | N4: Trend verdict
A5: =Indicators!A8 -> Asian Paints | B5: =Indicators!C5 -> 2.3794607 | C5: =Indicators!C8 -> 2.4631067 | D5: =IF(Indicators!C8>Indicators!C5*1.03,"Up",IF(Indicators!C8<Indicators!C5*0.97,"Down","Flat")) -> Up | E5: =Indicators!O5 -> 25.474303 | F5: =Indicators!O8 -> 17.53207 | G5: =IF(Indicators!O8>Indicators!O5*1.03,"Up",IF(Indicators!O8<Indicators!O5*0.97,"Down","Flat")) -> Down | H5: =Indicators!K5 -> 87.344633 | I5: =Indicators!K8 -> 74.862992 | J5: =IF(Indicators!K8>Indicators!K5*1.03,"Up",IF(Indicators!K8<Indicators!K5*0.97,"Down","Flat")) -> Down | K5: =Indicators!N5 -> 0.72394392 | L5: =Indicators!N8 -> 0.96503794 | M5: =IF(Indicators!N8>Indicators!N5*1.03,"Up",IF(Indicators!N8<Indicators!N5*0.97,"Down","Flat")) -> Up | N5: =IF((IF(Indicators!C8<Indicators!C5,1,0)+IF(Indicators!O8<Indicators!O5,1,0)+IF(Indicators!N8<Indicators!N5,1,0)+IF(Indicators!K8>Indicators!K5,1,0))>=3,"Deteriorating",IF((IF(Indicators!C8<Indicators!C5,1,0)+IF(Indicators!O8<Indicators!O5,1,0)+IF(Indicators!N8<Indicators!N5,1,0)+IF(Indicators!K8>Indicators!K5,1,0))=2,"Weakening","Stable / improving")) -> Stable / improving
A6: =Indicators!A12 -> Berger Paints | B6: =Indicators!C9 -> 1.3353746 | C6: =Indicators!C12 -> 2.1849998 | D6: =IF(Indicators!C12>Indicators!C9*1.03,"Up",IF(Indicators!C12<Indicators!C9*0.97,"Down","Flat")) -> Up | E6: =Indicators!O9 -> 14.952412 | F6: =Indicators!O12 -> 17.691482 | G6: =IF(Indicators!O12>Indicators!O9*1.03,"Up",IF(Indicators!O12<Indicators!O9*0.97,"Down","Flat")) -> Up | H6: =Indicators!K9 -> 65.70286 | I6: =Indicators!K12 -> 81.155519 | J6: =IF(Indicators!K12>Indicators!K9*1.03,"Up",IF(Indicators!K12<Indicators!K9*0.97,"Down","Flat")) -> Up | K6: =Indicators!N9 -> 0.34654288 | L6: =Indicators!N12 -> 0.65656292 | M6: =IF(Indicators!N12>Indicators!N9*1.03,"Up",IF(Indicators!N12<Indicators!N9*0.97,"Down","Flat")) -> Up | N6: =IF((IF(Indicators!C12<Indicators!C9,1,0)+IF(Indicators!O12<Indicators!O9,1,0)+IF(Indicators!N12<Indicators!N9,1,0)+IF(Indicators!K12>Indicators!K9,1,0))>=3,"Deteriorating",IF((IF(Indicators!C12<Indicators!C9,1,0)+IF(Indicators!O12<Indicators!O9,1,0)+IF(Indicators!N12<Indicators!N9,1,0)+IF(Indicators!K12>Indicators!K9,1,0))=2,"Weakening","Stable / improving")) -> Stable / improving
A7: =Indicators!A16 -> Kansai Nerolac | B7: =Indicators!C13 -> 2.8483116 | C7: =Indicators!C16 -> 3.7476689 | D7: =IF(Indicators!C16>Indicators!C13*1.03,"Up",IF(Indicators!C16<Indicators!C13*0.97,"Down","Flat")) -> Up | E7: =Indicators!O13 -> 14.266029 | F7: =Indicators!O16 -> 9.3749029 | G7: =IF(Indicators!O16>Indicators!O13*1.03,"Up",IF(Indicators!O16<Indicators!O13*0.97,"Down","Flat")) -> Down | H7: =Indicators!K13 -> 109.91957 | I7: =Indicators!K16 -> 95.527349 | J7: =IF(Indicators!K16>Indicators!K13*1.03,"Up",IF(Indicators!K16<Indicators!K13*0.97,"Down","Flat")) -> Down | K7: =Indicators!N13 -> 0.30880624 | L7: =Indicators!N16 -> 0.59094641 | M7: =IF(Indicators!N16>Indicators!N13*1.03,"Up",IF(Indicators!N16<Indicators!N13*0.97,"Down","Flat")) -> Up | N7: =IF((IF(Indicators!C16<Indicators!C13,1,0)+IF(Indicators!O16<Indicators!O13,1,0)+IF(Indicators!N16<Indicators!N13,1,0)+IF(Indicators!K16>Indicators!K13,1,0))>=3,"Deteriorating",IF((IF(Indicators!C16<Indicators!C13,1,0)+IF(Indicators!O16<Indicators!O13,1,0)+IF(Indicators!N16<Indicators!N13,1,0)+IF(Indicators!K16>Indicators!K13,1,0))=2,"Weakening","Stable / improving")) -> Stable / improving
A10: Chart data - Altman Z by year
A11: Year | B11: Asian Paints | C11: Berger Paints | D11: Kansai Nerolac
A12: =Inputs!B5 -> FY23 | B12: =Indicators!O5 -> 25.474303 | C12: =Indicators!O9 -> 14.952412 | D12: =Indicators!O13 -> 14.266029
A13: =Inputs!B6 -> FY24 | B13: =Indicators!O6 -> 25.41031 | C13: =Indicators!O10 -> 16.807126 | D13: =Indicators!O14 -> 12.485311
A14: =Inputs!B7 -> FY25 | B14: =Indicators!O7 -> 20.353492 | C14: =Indicators!O11 -> 16.564088 | D14: =Indicators!O15 -> 9.8201808
A15: =Inputs!B8 -> FY26 | B15: =Indicators!O8 -> 17.53207 | C15: =Indicators!O12 -> 17.691482 | D15: =Indicators!O16 -> 9.3749029
A17: Chart data - Current ratio by year
A18: Year | B18: Asian Paints | C18: Berger Paints | D18: Kansai Nerolac
A19: =Inputs!B5 -> FY23 | B19: =Indicators!C5 -> 2.3794607 | C19: =Indicators!C9 -> 1.3353746 | D19: =Indicators!C13 -> 2.8483116
A20: =Inputs!B6 -> FY24 | B20: =Indicators!C6 -> 2.3393645 | C20: =Indicators!C10 -> 1.7796608 | D20: =Indicators!C14 -> 3.4827426
A21: =Inputs!B7 -> FY25 | B21: =Indicators!C7 -> 2.3004929 | C21: =Indicators!C11 -> 2.0817219 | D21: =Indicators!C15 -> 4.018985
A22: =Inputs!B8 -> FY26 | B22: =Indicators!C8 -> 2.4631067 | C22: =Indicators!C12 -> 2.1849998 | D22: =Indicators!C16 -> 3.7476689

Sheet BENCHMARK_ANALYSIS
A1: Peer Benchmark Analysis
A2: Each company is benchmarked against the median of the other two (own value excluded) - shown separately from the fixed distress-threshold test. All company values link to 'Indicators'.
A4: Reference: distress thresholds and settings
A5: Metric | B5: Distress if | C5: Distress threshold | D5: Watch (amber) threshold | E5: Source in workbook (thresholds transcribed - see note 4)
A6: Current ratio | B6: Below | C6: 1 | D6: 1.5 | E6: Guide C6; Scorecard B5:B7 flag formula
A7: Quick ratio | B7: Below | C7: 0.7 | D7: 1 | E7: Guide C7; Scorecard C5:C7 flag formula
A8: WC / Total assets | B8: Below | C8: 0 | D8: 0.1 | E8: Guide C9; Scorecard D5:D7 flag formula
A9: Interest coverage (x) | B9: Below | C9: 1.5 | D9: 3 | E9: Guide C12; Scorecard E5:E7 flag formula
A10: Liabilities / EBITDA (x) | B10: Above | C10: 4 | D10: 3 | E10: Guide C13; Scorecard F5:F7 (also distress if negative)
A11: OCF / Current liabilities | B11: Below | C11: 0 | D11: 0.4 | E11: Guide C14; Scorecard G5:G7 flag formula
A12: Altman Z (classic) | B12: Below | C12: 1.81 | D12: 2.99 | E12: Guide C15; Scorecard H5:H7, L5:L7
A13: Altman Z″ (private) | B13: Below | C13: 1.1 | D13: 2.6 | E13: Guide C16; Scorecard N5:N7
A15: In-line band (± % of benchmark) | C15: 0.05 | D15: Labelling assumption only: a variance within this band is tagged 'In line'. It does not change any figure.
A17: ="COMPANY 1 - "&UPPER(Indicators!A5) -> COMPANY 1 - ASIAN PAINTS
A18: ="Peer benchmark for "&Indicators!A5&" = median of "&Indicators!A9&" and "&Indicators!A13&" (same year; own value excluded)" -> Peer benchmark for Asian Paints = median of Berger Paints and Kansai Nerolac (same year; own value excluded)
A19: A. Company vs peer benchmark, FY23 - FY26
A20: Metric | B20: Better if | C20: =Inputs!B5 -> FY23 | D20: =Inputs!B6 -> FY24 | E20: =Inputs!B7 -> FY25 | F20: =Inputs!B8 -> FY26 | G20: Peer Benchmark (FY26) | H20: Variance (Co. − Peer) | I20: Variance % | J20: FY26 vs Benchmark
A21: Current ratio | B21: Higher | C21: =Indicators!C5 -> 2.3794607 | D21: =Indicators!C6 -> 2.3393645 | E21: =Indicators!C7 -> 2.3004929 | F21: =Indicators!C8 -> 2.4631067 | G21: =J38 -> 2.9663343 | H21: =IFERROR(F21-G21,"") -> -0.50322764 | I21: =IFERROR((F21-G21)/ABS(G21),"") -> -0.1696463 | J21: =IF(I21="","",IF(ABS(I21)<=$C$15,"In line",IF(B21="Neutral",IF(I21>0,"Above peers","Below peers"),IF(OR(AND(B21="Higher",I21>0),AND(B21="Lower",I21<0)),"Better","Weaker")))) -> Weaker
A22: Quick ratio | B22: Higher | C22: =Indicators!D5 -> 1.4668608 | D22: =Indicators!D6 -> 1.5236192 | E22: =Indicators!D7 -> 1.3624182 | F22: =Indicators!D8 -> 1.7744366 | G22: =J39 -> 1.9486053 | H22: =IFERROR(F22-G22,"") -> -0.17416872 | I22: =IFERROR((F22-G22)/ABS(G22),"") -> -0.08938122 | J22: =IF(I22="","",IF(ABS(I22)<=$C$15,"In line",IF(B22="Neutral",IF(I22>0,"Above peers","Below peers"),IF(OR(AND(B22="Higher",I22>0),AND(B22="Lower",I22<0)),"Better","Weaker")))) -> Weaker
A23: Cash ratio | B23: Higher | C23: =Indicators!E5 -> 0.026826901 | D23: =Indicators!E6 -> 0.052396637 | E23: =Indicators!E7 -> 0.028617533 | F23: =Indicators!E8 -> 0.056435451 | G23: =J40 -> 0.096912512 | H23: =IFERROR(F23-G23,"") -> -0.040477061 | I23: =IFERROR((F23-G23)/ABS(G23),"") -> -0.41766599 | J23: =IF(I23="","",IF(ABS(I23)<=$C$15,"In line",IF(B23="Neutral",IF(I23>0,"Above peers","Below peers"),IF(OR(AND(B23="Higher",I23>0),AND(B23="Lower",I23<0)),"Better","Weaker")))) -> Weaker
A24: WC / Total assets | B24: Higher | C24: =Indicators!G5 -> 0.35704958 | D24: =Indicators!G6 -> 0.32069248 | E24: =Indicators!G7 -> 0.30393642 | F24: =Indicators!G8 -> 0.34072136 | G24: =J41 -> 0.38292473 | H24: =IFERROR(F24-G24,"") -> -0.042203367 | I24: =IFERROR((F24-G24)/ABS(G24),"") -> -0.11021322 | J24: =IF(I24="","",IF(ABS(I24)<=$C$15,"In line",IF(B24="Neutral",IF(I24>0,"Above peers","Below peers"),IF(OR(AND(B24="Higher",I24>0),AND(B24="Lower",I24<0)),"Better","Weaker")))) -> Weaker
A25: DSO (days) | B25: Lower | C25: =Indicators!H5 -> 42.018613 | D25: =Indicators!H6 -> 42.988787 | E25: =Indicators!H7 -> 39.492423 | F25: =Indicators!H8 -> 38.2884 | G25: =J42 -> 52.31628 | H25: =IFERROR(F25-G25,"") -> -14.02788 | I25: =IFERROR((F25-G25)/ABS(G25),"") -> -0.26813604 | J25: =IF(I25="","",IF(ABS(I25)<=$C$15,"In line",IF(B25="Neutral",IF(I25>0,"Above peers","Below peers"),IF(OR(AND(B25="Higher",I25>0),AND(B25="Lower",I25<0)),"Better","Weaker")))) -> Better
A26: DIO (days) | B26: Lower | C26: =Indicators!I5 -> 105.98549 | D26: =Indicators!I6 -> 107.56986 | E26: =Indicators!I7 -> 127.1215 | F26: =Indicators!I8 -> 103.17899 | G26: =J43 -> 120.26125 | H26: =IFERROR(F26-G26,"") -> -17.082262 | I26: =IFERROR((F26-G26)/ABS(G26),"") -> -0.14204294 | J26: =IF(I26="","",IF(ABS(I26)<=$C$15,"In line",IF(B26="Neutral",IF(I26>0,"Above peers","Below peers"),IF(OR(AND(B26="Higher",I26>0),AND(B26="Lower",I26<0)),"Better","Weaker")))) -> Better
A27: DPO (days) | B27: Neutral | C27: =Indicators!J5 -> 60.659472 | D27: =Indicators!J6 -> 68.653591 | E27: =Indicators!J7 -> 67.898863 | F27: =Indicators!J8 -> 66.604397 | G27: =J44 -> 84.236097 | H27: =IFERROR(F27-G27,"") -> -17.6317 | I27: =IFERROR((F27-G27)/ABS(G27),"") -> -0.20931288 | J27: =IF(I27="","",IF(ABS(I27)<=$C$15,"In line",IF(B27="Neutral",IF(I27>0,"Above peers","Below peers"),IF(OR(AND(B27="Higher",I27>0),AND(B27="Lower",I27<0)),"Better","Weaker")))) -> Below peers
A28: Cash conversion cycle (days) | B28: Lower | C28: =Indicators!K5 -> 87.344633 | D28: =Indicators!K6 -> 81.905059 | E28: =Indicators!K7 -> 98.715063 | F28: =Indicators!K8 -> 74.862992 | G28: =J45 -> 88.341434 | H28: =IFERROR(F28-G28,"") -> -13.478442 | I28: =IFERROR((F28-G28)/ABS(G28),"") -> -0.15257215 | J28: =IF(I28="","",IF(ABS(I28)<=$C$15,"In line",IF(B28="Neutral",IF(I28>0,"Above peers","Below peers"),IF(OR(AND(B28="Higher",I28>0),AND(B28="Lower",I28<0)),"Better","Weaker")))) -> Better
A29: Interest coverage (x) | B29: Higher | C29: =Indicators!L5 -> 59.989899 | D29: =Indicators!L6 -> 61.691735 | E29: =Indicators!L7 -> 37.73388 | F29: =Indicators!L8 -> 47.330035 | G29: =J46 -> 41.731726 | H29: =IFERROR(F29-G29,"") -> 5.5983093 | I29: =IFERROR((F29-G29)/ABS(G29),"") -> 0.13414996 | J29: =IF(I29="","",IF(ABS(I29)<=$C$15,"In line",IF(B29="Neutral",IF(I29>0,"Above peers","Below peers"),IF(OR(AND(B29="Higher",I29>0),AND(B29="Lower",I29<0)),"Better","Weaker")))) -> Better
A30: Liabilities / EBITDA (x) | B30: Lower | C30: =Indicators!M5 -> 1.0955732 | D30: =Indicators!M6 -> 0.96204432 | E30: =Indicators!M7 -> 1.215096 | F30: =Indicators!M8 -> 1.3078209 | G30: =J47 -> 1.5017647 | H30: =IFERROR(F30-G30,"") -> -0.19394378 | I30: =IFERROR((F30-G30)/ABS(G30),"") -> -0.12914392 | J30: =IF(I30="","",IF(ABS(I30)<=$C$15,"In line",IF(B30="Neutral",IF(I30>0,"Above peers","Below peers"),IF(OR(AND(B30="Higher",I30>0),AND(B30="Lower",I30<0)),"Better","Weaker")))) -> Better
A31: OCF / Current liabilities | B31: Higher | C31: =Indicators!N5 -> 0.72394392 | D31: =Indicators!N6 -> 0.92233255 | E31: =Indicators!N7 -> 0.66150596 | F31: =Indicators!N8 -> 0.96503794 | G31: =J48 -> 0.62375467 | H31: =IFERROR(F31-G31,"") -> 0.34128327 | I31: =IFERROR((F31-G31)/ABS(G31),"") -> 0.54714344 | J31: =IF(I31="","",IF(ABS(I31)<=$C$15,"In line",IF(B31="Neutral",IF(I31>0,"Above peers","Below peers"),IF(OR(AND(B31="Higher",I31>0),AND(B31="Lower",I31<0)),"Better","Weaker")))) -> Better
A32: Altman Z (classic) | B32: Higher | C32: =Indicators!O5 -> 25.474303 | D32: =Indicators!O6 -> 25.41031 | E32: =Indicators!O7 -> 20.353492 | F32: =Indicators!O8 -> 17.53207 | G32: =J49 -> 13.533193 | H32: =IFERROR(F32-G32,"") -> 3.9988775 | I32: =IFERROR((F32-G32)/ABS(G32),"") -> 0.29548663 | J32: =IF(I32="","",IF(ABS(I32)<=$C$15,"In line",IF(B32="Neutral",IF(I32>0,"Above peers","Below peers"),IF(OR(AND(B32="Higher",I32>0),AND(B32="Lower",I32<0)),"Better","Weaker")))) -> Better
A33: Altman Z″ (private) | B33: Higher | C33: =Indicators!P5 -> 8.6052881 | D33: =Indicators!P6 -> 8.8053073 | E33: =Indicators!P7 -> 8.2626056 | F33: =Indicators!P8 -> 8.1686741 | G33: =J50 -> 9.0329381 | H33: =IFERROR(F33-G33,"") -> -0.86426403 | I33: =IFERROR((F33-G33)/ABS(G33),"") -> -0.095679171 | J33: =IF(I33="","",IF(ABS(I33)<=$C$15,"In line",IF(B33="Neutral",IF(I33>0,"Above peers","Below peers"),IF(OR(AND(B33="Higher",I33>0),AND(B33="Lower",I33<0)),"Better","Weaker")))) -> Weaker
A35: B. Four-year peer benchmark: company actual vs peer median, every year
C36: Company actual | G36: Peer benchmark (median of the other two) | K36: Variance % vs peer benchmark
A37: Metric | B37: Better if | C37: =Inputs!B5 -> FY23 | D37: =Inputs!B6 -> FY24 | E37: =Inputs!B7 -> FY25 | F37: =Inputs!B8 -> FY26 | G37: =Inputs!B5 -> FY23 | H37: =Inputs!B6 -> FY24 | I37: =Inputs!B7 -> FY25 | J37: =Inputs!B8 -> FY26 | K37: =Inputs!B5 -> FY23 | L37: =Inputs!B6 -> FY24 | M37: =Inputs!B7 -> FY25 | N37: =Inputs!B8 -> FY26
A38: Current ratio | B38: Higher | C38: =Indicators!C5 -> 2.3794607 | D38: =Indicators!C6 -> 2.3393645 | E38: =Indicators!C7 -> 2.3004929 | F38: =Indicators!C8 -> 2.4631067 | G38: =IFERROR(MEDIAN(Indicators!C9,Indicators!C13),"") -> 2.0918431 | H38: =IFERROR(MEDIAN(Indicators!C10,Indicators!C14),"") -> 2.6312017 | I38: =IFERROR(MEDIAN(Indicators!C11,Indicators!C15),"") -> 3.0503534 | J38: =IFERROR(MEDIAN(Indicators!C12,Indicators!C16),"") -> 2.9663343 | K38: =IFERROR((C38-G38)/ABS(G38),"") -> 0.13749483 | L38: =IFERROR((D38-H38)/ABS(H38),"") -> -0.11091404 | M38: =IFERROR((E38-I38)/ABS(I38),"") -> -0.24582742 | N38: =IFERROR((F38-J38)/ABS(J38),"") -> -0.1696463
A39: Quick ratio | B39: Higher | C39: =Indicators!D5 -> 1.4668608 | D39: =Indicators!D6 -> 1.5236192 | E39: =Indicators!D7 -> 1.3624182 | F39: =Indicators!D8 -> 1.7744366 | G39: =IFERROR(MEDIAN(Indicators!D9,Indicators!D13),"") -> 1.034935 | H39: =IFERROR(MEDIAN(Indicators!D10,Indicators!D14),"") -> 1.5206438 | I39: =IFERROR(MEDIAN(Indicators!D11,Indicators!D15),"") -> 1.8695349 | J39: =IFERROR(MEDIAN(Indicators!D12,Indicators!D16),"") -> 1.9486053 | K39: =IFERROR((C39-G39)/ABS(G39),"") -> 0.41734588 | L39: =IFERROR((D39-H39)/ABS(H39),"") -> 0.0019566293 | M39: =IFERROR((E39-I39)/ABS(I39),"") -> -0.27125287 | N39: =IFERROR((F39-J39)/ABS(J39),"") -> -0.08938122
A40: Cash ratio | B40: Higher | C40: =Indicators!E5 -> 0.026826901 | D40: =Indicators!E6 -> 0.052396637 | E40: =Indicators!E7 -> 0.028617533 | F40: =Indicators!E8 -> 0.056435451 | G40: =IFERROR(MEDIAN(Indicators!E9,Indicators!E13),"") -> 0.046617964 | H40: =IFERROR(MEDIAN(Indicators!E10,Indicators!E14),"") -> 0.098887363 | I40: =IFERROR(MEDIAN(Indicators!E11,Indicators!E15),"") -> 0.068894695 | J40: =IFERROR(MEDIAN(Indicators!E12,Indicators!E16),"") -> 0.096912512 | K40: =IFERROR((C40-G40)/ABS(G40),"") -> -0.42453727 | L40: =IFERROR((D40-H40)/ABS(H40),"") -> -0.4701382 | M40: =IFERROR((E40-I40)/ABS(I40),"") -> -0.58461921 | N40: =IFERROR((F40-J40)/ABS(J40),"") -> -0.41766599
A41: WC / Total assets | B41: Higher | C41: =Indicators!G5 -> 0.35704958 | D41: =Indicators!G6 -> 0.32069248 | E41: =Indicators!G7 -> 0.30393642 | F41: =Indicators!G8 -> 0.34072136 | G41: =IFERROR(MEDIAN(Indicators!G9,Indicators!G13),"") -> 0.2513337 | H41: =IFERROR(MEDIAN(Indicators!G10,Indicators!G14),"") -> 0.33056026 | I41: =IFERROR(MEDIAN(Indicators!G11,Indicators!G15),"") -> 0.37519377 | J41: =IFERROR(MEDIAN(Indicators!G12,Indicators!G16),"") -> 0.38292473 | K41: =IFERROR((C41-G41)/ABS(G41),"") -> 0.42061963 | L41: =IFERROR((D41-H41)/ABS(H41),"") -> -0.029851669 | M41: =IFERROR((E41-I41)/ABS(I41),"") -> -0.18992145 | N41: =IFERROR((F41-J41)/ABS(J41),"") -> -0.11021322
A42: DSO (days) | B42: Lower | C42: =Indicators!H5 -> 42.018613 | D42: =Indicators!H6 -> 42.988787 | E42: =Indicators!H7 -> 39.492423 | F42: =Indicators!H8 -> 38.2884 | G42: =IFERROR(MEDIAN(Indicators!H9,Indicators!H13),"") -> 47.499879 | H42: =IFERROR(MEDIAN(Indicators!H10,Indicators!H14),"") -> 47.866485 | I42: =IFERROR(MEDIAN(Indicators!H11,Indicators!H15),"") -> 51.209608 | J42: =IFERROR(MEDIAN(Indicators!H12,Indicators!H16),"") -> 52.31628 | K42: =IFERROR((C42-G42)/ABS(G42),"") -> -0.11539536 | L42: =IFERROR((D42-H42)/ABS(H42),"") -> -0.10190214 | M42: =IFERROR((E42-I42)/ABS(I42),"") -> -0.22880833 | N42: =IFERROR((F42-J42)/ABS(J42),"") -> -0.26813604
A43: DIO (days) | B43: Lower | C43: =Indicators!I5 -> 105.98549 | D43: =Indicators!I6 -> 107.56986 | E43: =Indicators!I7 -> 127.1215 | F43: =Indicators!I8 -> 103.17899 | G43: =IFERROR(MEDIAN(Indicators!I9,Indicators!I13),"") -> 125.03781 | H43: =IFERROR(MEDIAN(Indicators!I10,Indicators!I14),"") -> 123.22358 | I43: =IFERROR(MEDIAN(Indicators!I11,Indicators!I15),"") -> 126.67983 | J43: =IFERROR(MEDIAN(Indicators!I12,Indicators!I16),"") -> 120.26125 | K43: =IFERROR((C43-G43)/ABS(G43),"") -> -0.15237242 | L43: =IFERROR((D43-H43)/ABS(H43),"") -> -0.12703512 | M43: =IFERROR((E43-I43)/ABS(I43),"") -> 0.0034865334 | N43: =IFERROR((F43-J43)/ABS(J43),"") -> -0.14204294
A44: DPO (days) | B44: Neutral | C44: =Indicators!J5 -> 60.659472 | D44: =Indicators!J6 -> 68.653591 | E44: =Indicators!J7 -> 67.898863 | F44: =Indicators!J8 -> 66.604397 | G44: =IFERROR(MEDIAN(Indicators!J9,Indicators!J13),"") -> 84.726468 | H44: =IFERROR(MEDIAN(Indicators!J10,Indicators!J14),"") -> 86.832011 | I44: =IFERROR(MEDIAN(Indicators!J11,Indicators!J15),"") -> 85.537624 | J44: =IFERROR(MEDIAN(Indicators!J12,Indicators!J16),"") -> 84.236097 | K44: =IFERROR((C44-G44)/ABS(G44),"") -> -0.28405522 | L44: =IFERROR((D44-H44)/ABS(H44),"") -> -0.2093516 | M44: =IFERROR((E44-I44)/ABS(I44),"") -> -0.20621055 | N44: =IFERROR((F44-J44)/ABS(J44),"") -> -0.20931288
...
