Workbook

Sheet Cover
B2: PORTFOLIO MANAGEMENT GROUP PROJECT
B3: Portfolio Construction, Performance Analysis and Investor Recommendations
C4: TEAM NUMBER 10
B6: Allocated Sector / Benchmark | C6: Power sector - benchmark identity to be confirmed (see Data Sources & Assumptions)
B8: Analysis Period | C8: Full 5 years of daily trading data (20-Sep-2021 to 16-Sep-2026, 1,238 trading days). ALL calculations (portfolios, correlation, covariance, Markowitz, benchmark, performance ratios) use DAILY returns (1,237 usable observations), annualised on a 252-trading-day basis. Superseded monthly sheets are kept for audit history only.
B10: Companies Selected (10) | C10: Adani Energy Solutions, Adani Green, Adani Power, CESC, JSW Energy, NHPC, NTPC, Power Grid, Tata Power, Torrent Power
B12: Nme | C12: Prajjwal Singh (153)
B14: Faculty | C14: Prof Pankajj Goel
B16: Status | C16: COMPLETE: fundamental analysis now includes a 3-year (FY23-FY25) revenue/profit/margin trend per company (not just a snapshot); criteria-based weighting uses a fixed-threshold scoring rubric (ROE, ROCE, growth, valuation) instead of relative normalisation; Dashboard adds a Rs 10,00,000 common-investment growth comparison across all six portfolios. Workbook trimmed to 18 active sheets (the two disconnected monthly-basis sheets were removed). Two open items remain: (1) confirm the benchmark index identity (Nifty Power vs Nifty Energy), and (2) the two mutual funds' risk metrics are provider-reported, not computed on the same daily basis as Portfolios 1-4.

Sheet Data Sources & Assumptions
B2: Data Sources and Assumptions
B4: Item | C4: Status / Note | D4: Needs action?
B5: Price data source | C5: Not stated in the uploaded workbook - confirm and record here (e.g. NSE India, Yahoo Finance, Screener, Bloomberg) before submission | D5: ACTION NEEDED
B6: Analysis period (daily) | C6: 20-Sep-2021 to 16-Sep-2026, 1,238 trading days, verified continuous with no missing prices or duplicate dates | D6: OK
B7: Analysis period (monthly) | C7: SUPERSEDED: the workbook now uses DAILY returns throughout, not monthly. The Monthly Prices/Monthly Returns sheets are kept for audit history only and are marked superseded - no live formula in the workbook reads from them anymore. | D7: RESOLVED
B8: Return frequency used | C8: DAILY (changed from monthly). Every portfolio, the benchmark, the correlation/covariance matrices, and Markowitz optimisation are computed on the full 1,237-day daily return series (21-Sep-2021 to 16-Sep-2026), per the group/faculty requirement to use daily data. Annualisation: (1 + average daily return)^252 - 1 for return; daily standard deviation x SQRT(252) for risk, using the standard 252-trading-day convention for the Indian market. | D8: RESOLVED
B9: Benchmark - FLAG | C9: Labelled 'Nifty Power (Energy)' in the raw data. Price level (~Rs 37,000) matches the Nifty Energy Index (broad energy incl. oil & gas), not the Nifty Power Index (~Rs 9,000, pure power/utilities). The 10 selected companies match Nifty Power Index constituents far more closely. CONFIRM the actual allocated benchmark and, if needed, replace this series with verified Nifty Power Index data from niftyindices.com. | D9: ACTION NEEDED
B10: Price adjustment status | C10: Not confirmed whether prices are adjusted for splits/bonuses/dividends. Needs verification against the source before final submission. | D10: ACTION NEEDED
B11: Risk-free rate | C11: 91-day Treasury Bill, cut-off yield ~5.28% at the 6-Aug-2026 RBI auction (rounded to 5.30% p.a. and held constant across the period as a disclosed simplification). Source: ICRA Analytics / Aditya Birla daily fixed-income tracker, 6-Aug-2026. | D11: RESOLVED
B12: Mutual fund data (Portfolios 5 and 6) | C12: Beta, Sharpe, Std. Dev. and Alpha for both funds are now shown on their sheets and in the Dashboard, sourced from advisorkhoj.com (retrieved Sep-2026), matched to the exact Growth plan cited elsewhere in this workbook. IMPORTANT CAVEAT: these are the provider's own risk figures (typically a 3-year, monthly-return basis with their own risk-free assumption) - NOT computed on the same 5-year, daily-return, 91-day-T-Bill basis as Portfolios 1-4. Treynor ratio for both funds is a mixed-source calculation: our own 5-year CAGR and risk-free rate combined with the provider's beta. A fully like-for-like comparison would require downloading each fund's actual daily or monthly NAV history from amfiindia.com. | D12: PARTIALLY RESOLVED
B13: Fundamental data (10 companies) | C13: Extended beyond a single snapshot: Fundamental Analysis now also carries a 3-year (FY23-FY25) Revenue, Net Profit and Operating Margin trend per company, sourced from company results announcements via Business Standard / Capital Market News (retrieved Sep-2026), with revenue and profit growth computed live via formula. Adani Green uses Operating Profit instead of Net Profit for the trend, disclosed on the sheet, since a consistent consolidated Net Profit series was not obtained this session. | D13: RESOLVED
B14: Rebalancing assumption | C14: Buy-and-hold: weights set once at the start of the 5-year period and held constant (no interim rebalancing). This is the standard simplifying assumption for this kind of static, in-sample comparison and is stated explicitly here per the assignment requirement. | D14: RESOLVED
B15: Criteria portfolio methodology | C15: Rebuilt as a fixed-threshold scoring rubric (ROE, ROCE, latest revenue growth, P/E valuation - each scored 1-5 against defined bands, not ranked only against these 10 peers), replacing the earlier min-max normalisation. Weights: Profitability 30%, Efficiency 25%, Growth 25%, Valuation 20% (editable on the Fundamental Scoring sheet). This makes the weighting logic independently defensible in a viva, since a score of 4 on ROE means the same thing regardless of which companies happen to be in the sample. | D15: RESOLVED
... B17: Workbook cleanup | C17: The two superseded monthly-basis sheets (Monthly Prices, Monthly Returns) have been deleted - they were fully disconnected from every downstream formula once the workbook moved to daily-return calculations, and kept no unique data (all of it survives in the daily Historical Data / Daily Returns sheets). 18 active sheets remain, each referenced by at least one other sheet. | D17: DONE

Sheet Data Audit
B2: Data Audit - Historical Data Sheet
B4: Data item | C4: Available / Missing | D4: Accuracy concern | E4: Required correction | F4: Priority
B5: Daily prices, 10 companies + benchmark | C5: Available | D5: None found - no missing prices, no duplicate dates, chronologically sorted | E5: None | F5: OK
B6: Date coverage | C6: Available | D6: 1,238 trading days, 20-Sep-2021 to 16-Sep-2026; one Saturday session (1-Feb-2025) is a genuine NSE special session, not an error | E6: None | F6: OK
B7: Data frequency | C7: Available (daily) | D7: Faculty/group requirement is DAILY (updated from an earlier monthly approach) | E7: Used natively - see Daily Returns sheet (1,237 daily observations); no conversion needed since source data was already daily | F7: Done
B8: Benchmark identity | C8: Available but mismatched | D8: Labelled 'Nifty Power (Energy)' but price level matches Nifty Energy Index, not Nifty Power Index which the 10 companies actually track | E8: Confirm allocated benchmark; replace with verified index series if needed | F8: HIGH
B9: Price adjustment (splits/bonus/dividends) | C9: Unconfirmed | D9: Cannot verify adjustment status from the file alone | E9: Confirm with data source | F9: MEDIUM
B10: Risk-free rate | C10: Missing | D10: Not present anywhere in the workbook | E10: Add T-Bill or G-Sec series matched to the analysis period | F10: HIGH
B11: Fundamental ratios (10 companies) | C11: Missing | D11: No ROE, ROCE, margins, P/E, P/B, growth data | E11: Source from annual reports / NSE-BSE disclosures / screener.in | F11: HIGH
B12: Mutual fund NAV data (2 schemes) | C12: Missing | D12: Not present | E12: Source from AMFI / fund house, 5-year growth-option NAV | F12: HIGH
B13: Source documentation | C13: Missing | D13: No source names, URLs, or retrieval dates recorded | E13: Add to Data Sources & Assumptions sheet | F13: HIGH

Sheet Fundamental Analysis
B2: Fundamental Analysis of the 10 Selected Companies
B3: Sector allocation: Power. Columns C-J are point-in-time snapshots (mid-September 2026). Columns K onward are a 3-year financial trend (FY23-FY25) sourced from company results announcements (Business Standard / Capital Market), added to satisfy the assignment requirement to show revenue and profit growth over the period, not just a single snapshot.
B5: Company | C5: Business Description | D5: Market Cap (Rs Cr) | E5: P/E (x) | F5: Book Value (Rs) | H5: ROE % | I5: ROCE % | J5: Source | K5: Revenue FY23 (Rs Cr) | L5: Revenue FY24 (Rs Cr) | M5: Revenue FY25 (Rs Cr) | N5: Revenue Growth FY24 % | O5: Revenue Growth FY25 % | P5: Profit FY23 (Rs Cr) | Q5: Profit FY24 (Rs Cr) | R5: Profit FY25 (Rs Cr) | S5: Profit Growth FY24 % | T5: Profit Growth FY25 % | U5: OPM FY23 % | V5: OPM FY24 % | W5: OPM FY25 % | X5: Profit Metric / Note
B6: Adani Energy Solutions | C6: Power transmission, distribution and smart metering (GTD) business; India's largest private transmission company. | D6: 112014 | E6: 180.9 | F6: 166.9 | H6: 0.0403 | I6: 0.0529 | J6: ticker.finology.in, Sep-2026 | K6: 13292.72 | L6: 16607.36 | M6: 23767.09 | N6: =L6/K6-1 -> 0.24935754 | O6: =M6/L6-1 -> 0.43111789 | P6: 1256.33 | Q6: 1137.28 | R6: 1059.97 | S6: =Q6/P6-1 -> -0.094760135 | T6: =R6/Q6-1 -> -0.067977983 | U6: 0.3399 | V6: 0.3439 | W6: 0.2973 | X6: Net Profit
B7: Adani Green | C7: India's largest pure-play renewable energy IPP; solar, wind and hybrid generation. | D7: 214347 | E7: 313 | F7: 90.4 | H7: 0.071 | I7: 0.0598 | J7: screener.in (consolidated), 04-Sep-2026 | K7: 7792 | L7: 9220 | M7: 11212 | N7: =L7/K7-1 -> 0.18326489 | O7: =M7/L7-1 -> 0.21605206 | P7: 4970 | Q7: 7339 | R7: 8889 | S7: =Q7/P7-1 -> 0.47665996 | T7: =R7/Q7-1 -> 0.21120044 | U7: 0.64 | V7: 0.8 | W7: 0.79 | X7: Operating Profit (Net Profit series was inconsistent across sources this session)
B8: Adani Power | C8: Largest private thermal (coal-based) power producer in India; also has power trading operations. | D8: 401700 | E8: 28.2 | F8: 33.7 | H8: 0.211 | I8: 0.172 | J8: screener.in (consolidated), 18-Sep-2026 | K8: 38773.3 | L8: 50351.25 | M8: 56203.09 | N8: =L8/K8-1 -> 0.29860626 | O8: =M8/L8-1 -> 0.11622035 | P8: 10726.64 | Q8: 20828.79 | R8: 12938.77 | S8: =Q8/P8-1 -> 0.9417814 | T8: =R8/Q8-1 -> -0.37880357 | U8: 0.2591 | V8: 0.3611 | W8: 0.3791 | X8: Net Profit
B9: CESC | C9: Integrated power utility generating and distributing electricity to Kolkata and licensed areas in Maharashtra, Rajasthan; part of RP-Sanjiv Goenka Group. | D9: 22707 | E9: 16.6 | F9: 90.6 | H9: 0.117 | I9: 0.109 | J9: screener.in (consolidated) | K9: 14246 | L9: 15293 | M9: 17001 | N9: =L9/K9-1 -> 0.073494314 | O9: =M9/L9-1 -> 0.11168508 | P9: 1343 | Q9: 1376 | R9: 1369 | S9: =Q9/P9-1 -> 0.024571854 | T9: =R9/Q9-1 -> -0.0050872093 | U9: 0.1508 | V9: 0.139 | W9: 0.1582 | X9: Net Profit
B10: JSW Energy | C10: Independent power producer (thermal, hydro, wind, solar) and part of the JSW Group; expanding into battery storage and pumped hydro. | D10: 89314 | E10: 99.3 | F10: 130 | H10: 0.0624 | I10: 0.0582 | J10: screener.in | K10: 10331.81 | L10: 11485.91 | M10: 11745.39 | N10: =L10/K10-1 -> 0.11170356 | O10: =M10/L10-1 -> 0.022591157 | P10: 1477.76 | Q10: 1722.71 | R10: 1950.89 | S10: =Q10/P10-1 -> 0.16575763 | T10: =R10/Q10-1 -> 0.1324541 | U10: 0.143 | V10: 0.15 | W10: 0.1661 | X10: Net Profit (margin shown is Net Profit Margin; OPM not captured this session)
B11: NHPC | C11: Government of India Mini Ratna; India's largest hydropower generation company, also expanding into solar and wind. | D11: 80250 | E11: 29.6 | F11: 40 | H11: 0.0961 | I11: 0.0767 | J11: screener.in (consolidated) | K11: 10607.4 | L11: 9630.96 | M11: 10379.86 | N11: =L11/K11-1 -> -0.092052718 | O11: =M11/L11-1 -> 0.077759642 | P11: 3903.31 | Q11: 3595.95 | R11: 3006.67 | S11: =Q11/P11-1 -> -0.078743425 | T11: =R11/Q11-1 -> -0.16387325 | U11: 0.5891 | V11: 0.538 | W11: 0.5318 | X11: Net Profit
B12: NTPC | C12: India's largest power generation company (Maharatna PSU); coal, gas and increasingly renewable generation plus consultancy. | D12: 335797 | E12: 15.3 | F12: 174 | H12: 0.136 | I12: 0.105 | J12: screener.in (consolidated) | K12: 176206.93 | L12: 178524.8 | M12: 188138.06 | N12: =L12/K12-1 -> 0.01315425 | O12: =M12/L12-1 -> 0.053848317 | P12: 16912.55 | Q12: 20811.89 | R12: 23422.46 | S12: =Q12/P12-1 -> 0.23055896 | T12: =R12/Q12-1 -> 0.12543647 | U12: 0.2685 | V12: 0.2863 | W12: 0.2877 | X12: Net Profit
B13: Power Grid | C13: Central Transmission Utility of India (Maharatna PSU); owns and operates the national interstate power transmission network. | D13: 263951 | E13: 16.86 | F13: 108.05 | H13: 0.1637 | I13: 0.12 | J13: share.market (ROE) / tipranks.com (ROCE) | K13: 45581.28 | L13: 45843.1 | M13: 45792.32 | N13: =L13/K13-1 -> 0.0057440247 | O13: =M13/L13-1 -> -0.0011076912 | P13: 15419.74 | Q13: 15573.16 | R13: 15521.44 | S13: =Q13/P13-1 -> 0.0099495841 | T13: =R13/Q13-1 -> -0.0033210986 | U13: 0.8643 | V13: 0.8575 | W13: 0.8507 | X13: Net Profit
B14: Tata Power | C14: India's largest integrated private power company; generation, transmission, distribution, renewables, EV charging and solar rooftop. | D14: 116023 | E14: 30.6 | F14: 105 | H14: 0.113 | I14: 0.111 | J14: screener.in (consolidated) | K14: 55109.08 | L14: 61448.9 | M14: 65478.24 | N14: =L14/K14-1 -> 0.1150413 | O14: =M14/L14-1 -> 0.065572207 | P14: 3336.44 | Q14: 3696.25 | R14: 3971 | S14: =Q14/P14-1 -> 0.10784249 | T14: =R14/Q14-1 -> 0.074332093 | U14: 0.1398 | V14: 0.1755 | W14: 0.1978 | X14: Net Profit
B15: Torrent Power | C15: Integrated power utility (generation, transmission, distribution and renewables) across Gujarat, Maharashtra, UP and Karnataka; part of Torrent Group. | D15: 71738 | E15: 38.7 | F15: 247 | H15: 0.196 | I15: 0.183 | J15: screener.in (consolidated) | K15: 25694.12 | L15: 27183.21 | M15: 29165.26 | N15: =L15/K15-1 -> 0.057954505 | O15: =M15/L15-1 -> 0.072914494 | P15: 2117.43 | Q15: 1833.23 | R15: 2988.5 | S15: =Q15/P15-1 -> -0.13421931 | T15: =R15/Q15-1 -> 0.63018279 | U15: 0.1852 | V15: 0.1677 | W15: 0.182 | X15: Net Profit
K17: Source: company quarterly/annual results announcements via Business Standard - Capital Market News, retrieved Sep-2026 (individual URLs available on request; all figures are as originally reported, consolidated basis).

Sheet Fundamental Scoring
B2: Fundamental Scoring - Criteria-Based Weighting Methodology (Rubric-Based)
B3: Each company is scored 1 (weakest) to 5 (strongest) on four pillars against FIXED thresholds (not scored relative to just these 10 companies), so the score is independently defensible in a viva. Composite Score = weighted average of the four pillar scores (weights below, editable). Final Weight = Composite Score / SUM(all Composite Scores), so weights always sum to 100%.
D4: Profitability (ROE) | E4: Efficiency (ROCE) | F4: Growth (Revenue Growth FY25) | G4: Valuation (P/E, lower=better)
B5: Pillar Weight -> | D5: 0.3 | E5: 0.25 | F5: 0.25 | G5: 0.2
B7: Scoring Rubric (fixed thresholds, not relative to this peer set)
B8: ROE: >=18% -> 5 | 14-18% -> 4 | 10-14% -> 3 | 6-10% -> 2 | <6% -> 1
B9: ROCE: >=15% -> 5 | 12-15% -> 4 | 9-12% -> 3 | 6-9% -> 2 | <6% -> 1
B10: Revenue Growth (FY25): >=20% -> 5 | 12-20% -> 4 | 6-12% -> 3 | 0-6% -> 2 | <0% -> 1
B11: P/E (lower is better - cheaper): <=15x -> 5 | 15-20x -> 4 | 20-30x -> 3 | 30-50x -> 2 | >50x -> 1
B13: Company | C13: ROE % | D13: ROCE % | E13: Rev. Growth FY25 % | F13: P/E (x) | G13: ROE Score | H13: ROCE Score | I13: Growth Score | J13: Valuation Score | K13: Composite Score | L13: Weight %
B14: Adani Energy Solutions | C14: ='Fundamental Analysis'!H6 -> 0.0403 | D14: ='Fundamental Analysis'!I6 -> 0.0529 | E14: ='Fundamental Analysis'!O6 -> 0.43111789 | F14: ='Fundamental Analysis'!E6 -> 180.9 | G14: =IF(C14>=0.18,5,IF(C14>=0.14,4,IF(C14>=0.1,3,IF(C14>=0.06,2,1)))) -> 1 | H14: =IF(D14>=0.15,5,IF(D14>=0.12,4,IF(D14>=0.09,3,IF(D14>=0.06,2,1)))) -> 1 | I14: =IF(E14>=0.2,5,IF(E14>=0.12,4,IF(E14>=0.06,3,IF(E14>=0,2,1)))) -> 5 | J14: =IF(F14<=15,5,IF(F14<=20,4,IF(F14<=30,3,IF(F14<=50,2,1)))) -> 1 | K14: =G14*$D$5+H14*$E$5+I14*$F$5+J14*$G$5 -> 2 | L14: =K14/SUM($K$14:$K$23) -> 0.070175439
B15: Adani Green | C15: ='Fundamental Analysis'!H7 -> 0.071 | D15: ='Fundamental Analysis'!I7 -> 0.0598 | E15: ='Fundamental Analysis'!O7 -> 0.21605206 | F15: ='Fundamental Analysis'!E7 -> 313 | G15: =IF(C15>=0.18,5,IF(C15>=0.14,4,IF(C15>=0.1,3,IF(C15>=0.06,2,1)))) -> 2 | H15: =IF(D15>=0.15,5,IF(D15>=0.12,4,IF(D15>=0.09,3,IF(D15>=0.06,2,1)))) -> 1 | I15: =IF(E15>=0.2,5,IF(E15>=0.12,4,IF(E15>=0.06,3,IF(E15>=0,2,1)))) -> 5 | J15: =IF(F15<=15,5,IF(F15<=20,4,IF(F15<=30,3,IF(F15<=50,2,1)))) -> 1 | K15: =G15*$D$5+H15*$E$5+I15*$F$5+J15*$G$5 -> 2.3 | L15: =K15/SUM($K$14:$K$23) -> 0.080701754
B16: Adani Power | C16: ='Fundamental Analysis'!H8 -> 0.211 | D16: ='Fundamental Analysis'!I8 -> 0.172 | E16: ='Fundamental Analysis'!O8 -> 0.11622035 | F16: ='Fundamental Analysis'!E8 -> 28.2 | G16: =IF(C16>=0.18,5,IF(C16>=0.14,4,IF(C16>=0.1,3,IF(C16>=0.06,2,1)))) -> 5 | H16: =IF(D16>=0.15,5,IF(D16>=0.12,4,IF(D16>=0.09,3,IF(D16>=0.06,2,1)))) -> 5 | I16: =IF(E16>=0.2,5,IF(E16>=0.12,4,IF(E16>=0.06,3,IF(E16>=0,2,1)))) -> 3 | J16: =IF(F16<=15,5,IF(F16<=20,4,IF(F16<=30,3,IF(F16<=50,2,1)))) -> 3 | K16: =G16*$D$5+H16*$E$5+I16*$F$5+J16*$G$5 -> 4.1 | L16: =K16/SUM($K$14:$K$23) -> 0.14385965
B17: CESC | C17: ='Fundamental Analysis'!H9 -> 0.117 | D17: ='Fundamental Analysis'!I9 -> 0.109 | E17: ='Fundamental Analysis'!O9 -> 0.11168508 | F17: ='Fundamental Analysis'!E9 -> 16.6 | G17: =IF(C17>=0.18,5,IF(C17>=0.14,4,IF(C17>=0.1,3,IF(C17>=0.06,2,1)))) -> 3 | H17: =IF(D17>=0.15,5,IF(D17>=0.12,4,IF(D17>=0.09,3,IF(D17>=0.06,2,1)))) -> 3 | I17: =IF(E17>=0.2,5,IF(E17>=0.12,4,IF(E17>=0.06,3,IF(E17>=0,2,1)))) -> 3 | J17: =IF(F17<=15,5,IF(F17<=20,4,IF(F17<=30,3,IF(F17<=50,2,1)))) -> 4 | K17: =G17*$D$5+H17*$E$5+I17*$F$5+J17*$G$5 -> 3.2 | L17: =K17/SUM($K$14:$K$23) -> 0.1122807
B18: JSW Energy | C18: ='Fundamental Analysis'!H10 -> 0.0624 | D18: ='Fundamental Analysis'!I10 -> 0.0582 | E18: ='Fundamental Analysis'!O10 -> 0.022591157 | F18: ='Fundamental Analysis'!E10 -> 99.3 | G18: =IF(C18>=0.18,5,IF(C18>=0.14,4,IF(C18>=0.1,3,IF(C18>=0.06,2,1)))) -> 2 | H18: =IF(D18>=0.15,5,IF(D18>=0.12,4,IF(D18>=0.09,3,IF(D18>=0.06,2,1)))) -> 1 | I18: =IF(E18>=0.2,5,IF(E18>=0.12,4,IF(E18>=0.06,3,IF(E18>=0,2,1)))) -> 2 | J18: =IF(F18<=15,5,IF(F18<=20,4,IF(F18<=30,3,IF(F18<=50,2,1)))) -> 1 | K18: =G18*$D$5+H18*$E$5+I18*$F$5+J18*$G$5 -> 1.55 | L18: =K18/SUM($K$14:$K$23) -> 0.054385965
B19: NHPC | C19: ='Fundamental Analysis'!H11 -> 0.0961 | D19: ='Fundamental Analysis'!I11 -> 0.0767 | E19: ='Fundamental Analysis'!O11 -> 0.077759642 | F19: ='Fundamental Analysis'!E11 -> 29.6 | G19: =IF(C19>=0.18,5,IF(C19>=0.14,4,IF(C19>=0.1,3,IF(C19>=0.06,2,1)))) -> 2 | H19: =IF(D19>=0.15,5,IF(D19>=0.12,4,IF(D19>=0.09,3,IF(D19>=0.06,2,1)))) -> 2 | I19: =IF(E19>=0.2,5,IF(E19>=0.12,4,IF(E19>=0.06,3,IF(E19>=0,2,1)))) -> 3 | J19: =IF(F19<=15,5,IF(F19<=20,4,IF(F19<=30,3,IF(F19<=50,2,1)))) -> 3 | K19: =G19*$D$5+H19*$E$5+I19*$F$5+J19*$G$5 -> 2.45 | L19: =K19/SUM($K$14:$K$23) -> 0.085964912
B20: NTPC | C20: ='Fundamental Analysis'!H12 -> 0.136 | D20: ='Fundamental Analysis'!I12 -> 0.105 | E20: ='Fundamental Analysis'!O12 -> 0.053848317 | F20: ='Fundamental Analysis'!E12 -> 15.3 | G20: =IF(C20>=0.18,5,IF(C20>=0.14,4,IF(C20>=0.1,3,IF(C20>=0.06,2,1)))) -> 3 | H20: =IF(D20>=0.15,5,IF(D20>=0.12,4,IF(D20>=0.09,3,IF(D20>=0.06,2,1)))) -> 3 | I20: =IF(E20>=0.2,5,IF(E20>=0.12,4,IF(E20>=0.06,3,IF(E20>=0,2,1)))) -> 2 | J20: =IF(F20<=15,5,IF(F20<=20,4,IF(F20<=30,3,IF(F20<=50,2,1)))) -> 4 | K20: =G20*$D$5+H20*$E$5+I20*$F$5+J20*$G$5 -> 2.95 | L20: =K20/SUM($K$14:$K$23) -> 0.10350877
B21: Power Grid | C21: ='Fundamental Analysis'!H13 -> 0.1637 | D21: ='Fundamental Analysis'!I13 -> 0.12 | E21: ='Fundamental Analysis'!O13 -> -0.0011076912 | F21: ='Fundamental Analysis'!E13 -> 16.86 | G21: =IF(C21>=0.18,5,IF(C21>=0.14,4,IF(C21>=0.1,3,IF(C21>=0.06,2,1)))) -> 4 | H21: =IF(D21>=0.15,5,IF(D21>=0.12,4,IF(D21>=0.09,3,IF(D21>=0.06,2,1)))) -> 4 | I21: =IF(E21>=0.2,5,IF(E21>=0.12,4,IF(E21>=0.06,3,IF(E21>=0,2,1)))) -> 1 | J21: =IF(F21<=15,5,IF(F21<=20,4,IF(F21<=30,3,IF(F21<=50,2,1)))) -> 4 | K21: =G21*$D$5+H21*$E$5+I21*$F$5+J21*$G$5 -> 3.25 | L21: =K21/SUM($K$14:$K$23) -> 0.11403509
B22: Tata Power | C22: ='Fundamental Analysis'!H14 -> 0.113 | D22: ='Fundamental Analysis'!I14 -> 0.111 | E22: ='Fundamental Analysis'!O14 -> 0.065572207 | F22: ='Fundamental Analysis'!E14 -> 30.6 | G22: =IF(C22>=0.18,5,IF(C22>=0.14,4,IF(C22>=0.1,3,IF(C22>=0.06,2,1)))) -> 3 | H22: =IF(D22>=0.15,5,IF(D22>=0.12,4,IF(D22>=0.09,3,IF(D22>=0.06,2,1)))) -> 3 | I22: =IF(E22>=0.2,5,IF(E22>=0.12,4,IF(E22>=0.06,3,IF(E22>=0,2,1)))) -> 3 | J22: =IF(F22<=15,5,IF(F22<=20,4,IF(F22<=30,3,IF(F22<=50,2,1)))) -> 2 | K22: =G22*$D$5+H22*$E$5+I22*$F$5+J22*$G$5 -> 2.8 | L22: =K22/SUM($K$14:$K$23) -> 0.098245614
B23: Torrent Power | C23: ='Fundamental Analysis'!H15 -> 0.196 | D23: ='Fundamental Analysis'!I15 -> 0.183 | E23: ='Fundamental Analysis'!O15 -> 0.072914494 | F23: ='Fundamental Analysis'!E15 -> 38.7 | G23: =IF(C23>=0.18,5,IF(C23>=0.14,4,IF(C23>=0.1,3,IF(C23>=0.06,2,1)))) -> 5 | H23: =IF(D23>=0.15,5,IF(D23>=0.12,4,IF(D23>=0.09,3,IF(D23>=0.06,2,1)))) -> 5 | I23: =IF(E23>=0.2,5,IF(E23>=0.12,4,IF(E23>=0.06,3,IF(E23>=0,2,1)))) -> 3 | J23: =IF(F23<=15,5,IF(F23<=20,4,IF(F23<=30,3,IF(F23<=50,2,1)))) -> 2 | K23: =G23*$D$5+H23*$E$5+I23*$F$5+J23*$G$5 -> 3.9 | L23: =K23/SUM($K$14:$K$23) -> 0.13684211
B24: TOTAL | L24: =SUM(L14:L23) -> 1

Sheet Portfolio 1 - Equal Weight
B2: Portfolio 1: Equally Weighted Portfolio
B3: 10% weight to each of the 10 selected companies. Daily return = SUMPRODUCT(weights, company daily returns), linked live to the Daily Returns sheet (1,237 trading days).
B4: (helper row - weights mirrored horizontally for SUMPRODUCT) | D4: =C6 -> 0.1 | E4: =C7 -> 0.1 | F4: =C8 -> 0.1 | G4: =C9 -> 0.1 | H4: =C10 -> 0.1 | I4: =C11 -> 0.1 | J4: =C12 -> 0.1 | K4: =C13 -> 0.1 | L4: =C14 -> 0.1 | M4: =C15 -> 0.1
B5: Company | C5: Weight | E5: Date | F5: Portfolio Daily Return
B6: Adani Energy Solutions | C6: 0.1 | E6: ='Daily Returns'!B6 -> 44460 | F6: =SUMPRODUCT($D$4:$M$4,'Daily Returns'!D6:M6) -> -0.0078737931
B7: Adani Green | C7: 0.1 | E7: ='Daily Returns'!B7 -> 44461 | F7: =SUMPRODUCT($D$4:$M$4,'Daily Returns'!D7:M7) -> -0.0024220608
B8: Adani Power | C8: 0.1 | E8: ='Daily Returns'!B8 -> 44462 | F8: =SUMPRODUCT($D$4:$M$4,'Daily Returns'!D8:M8) -> 0.013150958
B9: CESC | C9: 0.1 | E9: ='Daily Returns'!B9 -> 44463 | F9: =SUMPRODUCT($D$4:$M$4,'Daily Returns'!D9:M9) -> -0.0084675047
B10: JSW Energy | C10: 0.1 | E10: ='Daily Returns'!B10 -> 44466 | F10: =SUMPRODUCT($D$4:$M$4,'Daily Returns'!D10:M10) -> 0.00203978
B11: NHPC | C11: 0.1 | E11: ='Daily Returns'!B11 -> 44467 | F11: =SUMPRODUCT($D$4:$M$4,'Daily Returns'!D11:M11) -> 0.014134331
B12: NTPC | C12: 0.1 | E12: ='Daily Returns'!B12 -> 44468 | F12: =SUMPRODUCT($D$4:$M$4,'Daily Returns'!D12:M12) -> 0.037921793
B13: Power Grid | C13: 0.1 | E13: ='Daily Returns'!B13 -> 44469 | F13: =SUMPRODUCT($D$4:$M$4,'Daily Returns'!D13:M13) -> 0.010823112
B14: Tata Power | C14: 0.1 | E14: ='Daily Returns'!B14 -> 44470 | F14: =SUMPRODUCT($D$4:$M$4,'Daily Returns'!D14:M14) -> -0.0003275499
B15: Torrent Power | C15: 0.1 | E15: ='Daily Returns'!B15 -> 44473 | F15: =SUMPRODUCT($D$4:$M$4,'Daily Returns'!D15:M15) -> 0.019260004
B16: TOTAL | C16: =SUM(C6:C15) -> 1 | E16: ='Daily Returns'!B16 -> 44474 | F16: =SUMPRODUCT($D$4:$M$4,'Daily Returns'!D16:M16) -> 0.026301847
E17: ='Daily Returns'!B17 -> 44475 | F17: =SUMPRODUCT($D$4:$M$4,'Daily Returns'!D17:M17) -> -0.012295777
E18: ='Daily Returns'!B18 -> 44476 | F18: =SUMPRODUCT($D$4:$M$4,'Daily Returns'!D18:M18) -> -0.00020149416
E19: ='Daily Returns'!B19 -> 44477 | F19: =SUMPRODUCT($D$4:$M$4,'Daily Returns'!D19:M19) -> -0.010577193
E20: ='Daily Returns'!B20 -> 44480 | F20: =SUMPRODUCT($D$4:$M$4,'Daily Returns'!D20:M20) -> 0.024334458
E21: ='Daily Returns'!B21 -> 44481 | F21: =SUMPRODUCT($D$4:$M$4,'Daily Returns'!D21:M21) -> -0.0016884724
E22: ='Daily Returns'!B22 -> 44482 | F22: =SUMPRODUCT($D$4:$M$4,'Daily Returns'!D22:M22) -> 0.026732478
E23: ='Daily Returns'!B23 -> 44483 | F23: =SUMPRODUCT($D$4:$M$4,'Daily Returns'!D23:M23) -> 0.015243384
E24: ='Daily Returns'!B24 -> 44487 | F24: =SUMPRODUCT($D$4:$M$4,'Daily Returns'!D24:M24) -> 0.049034974
E25: ='Daily Returns'!B25 -> 44488 | F25: =SUMPRODUCT($D$4:$M$4,'Daily Returns'!D25:M25) -> -0.025469091
E26: ='Daily Returns'!B26 -> 44489 | F26: =SUMPRODUCT($D$4:$M$4,'Daily Returns'!D26:M26) -> -0.020768582
E27: ='Daily Returns'!B27 -> 44490 | F27: =SUMPRODUCT($D$4:$M$4,'Daily Returns'!D27:M27) -> 0.0031616308
E28: ='Daily Returns'!B28 -> 44491 | F28: =SUMPRODUCT($D$4:$M$4,'Daily Returns'!D28:M28) -> -0.0019391672
... E1242: ='Daily Returns'!B1242 -> 46281 | F1242: =SUMPRODUCT($D$4:$M$4,'Daily Returns'!D1242:M1242) -> -0.0013089092
E1244: Average Daily Return | F1244: =AVERAGE(F6:F1242) -> 0.0010034079
E1245: Annualised Return (compounded, 252 trading days) | F1245: =(1+F1244)^252-1 -> 0.28753819
E1246: Daily Std. Dev. | F1246: =STDEV(F6:F1242) -> 0.015769568
E1247: Annualised Std. Dev. | F1247: =F1246*SQRT(252) -> 0.25033414

Sheet Portfolio 2 - Criteria Based
B2: Portfolio 2: Criteria-Based Portfolio (Composite Fundamental Score)
B3: Weights from the composite fundamental score (ROE, ROCE, inverse P/E) on the Fundamental Scoring sheet - unchanged by the return-frequency switch. Daily return = SUMPRODUCT(weights, company daily returns).
B4: (helper row - weights mirrored horizontally for SUMPRODUCT) | D4: =C6 -> 0.070175439 | E4: =C7 -> 0.080701754 | F4: =C8 -> 0.14385965 | G4: =C9 -> 0.1122807 | H4: =C10 -> 0.054385965 | I4: =C11 -> 0.085964912 | J4: =C12 -> 0.10350877 | K4: =C13 -> 0.11403509 | L4: =C14 -> 0.098245614 | M4: =C15 -> 0.13684211
B5: Company | C5: Weight | E5: Date | F5: Portfolio Daily Return
B6: Adani Energy Solutions | C6: ='Fundamental Scoring'!L14 -> 0.070175439 | E6: ='Daily Returns'!B6 -> 44460 | F6: =SUMPRODUCT($D$4:$M$4,'Daily Returns'!D6:M6) -> -0.0074747346
B7: Adani Green | C7: ='Fundamental Scoring'!L15 -> 0.080701754 | E7: ='Daily Returns'!B7 -> 44461 | F7: =SUMPRODUCT($D$4:$M$4,'Daily Returns'!D7:M7) -> -0.0010212169
B8: Adani Power | C8: ='Fundamental Scoring'!L16 -> 0.14385965 | E8: ='Daily Returns'!B8 -> 44462 | F8: =SUMPRODUCT($D$4:$M$4,'Daily Returns'!D8:M8) -> 0.012353631
B9: CESC | C9: ='Fundamental Scoring'!L17 -> 0.1122807 | E9: ='Daily Returns'!B9 -> 44463 | F9: =SUMPRODUCT($D$4:$M$4,'Daily Returns'!D9:M9) -> -0.0091423539
B10: JSW Energy | C10: ='Fundamental Scoring'!L18 -> 0.054385965 | E10: ='Daily Returns'!B10 -> 44466 | F10: =SUMPRODUCT($D$4:$M$4,'Daily Returns'!D10:M10) -> 0.0014929421
B11: NHPC | C11: ='Fundamental Scoring'!L19 -> 0.085964912 | E11: ='Daily Returns'!B11 -> 44467 | F11: =SUMPRODUCT($D$4:$M$4,'Daily Returns'!D11:M11) -> 0.013267485
B12: NTPC | C12: ='Fundamental Scoring'!L20 -> 0.10350877 | E12: ='Daily Returns'!B12 -> 44468 | F12: =SUMPRODUCT($D$4:$M$4,'Daily Returns'!D12:M12) -> 0.039222541
B13: Power Grid | C13: ='Fundamental Scoring'!L21 -> 0.11403509 | E13: ='Daily Returns'!B13 -> 44469 | F13: =SUMPRODUCT($D$4:$M$4,'Daily Returns'!D13:M13) -> 0.0082326286
B14: Tata Power | C14: ='Fundamental Scoring'!L22 -> 0.098245614 | E14: ='Daily Returns'!B14 -> 44470 | F14: =SUMPRODUCT($D$4:$M$4,'Daily Returns'!D14:M14) -> -0.00018375596
B15: Torrent Power | C15: ='Fundamental Scoring'!L23 -> 0.13684211 | E15: ='Daily Returns'!B15 -> 44473 | F15: =SUMPRODUCT($D$4:$M$4,'Daily Returns'!D15:M15) -> 0.020603456
B16: TOTAL | C16: =SUM(C6:C15) -> 1 | E16: ='Daily Returns'!B16 -> 44474 | F16: =SUMPRODUCT($D$4:$M$4,'Daily Returns'!D16:M16) -> 0.025550457
E17: ='Daily Returns'!B17 -> 44475 | F17: =SUMPRODUCT($D$4:$M$4,'Daily Returns'!D17:M17) -> -0.015222357
E18: ='Daily Returns'!B18 -> 44476 | F18: =SUMPRODUCT($D$4:$M$4,'Daily Returns'!D18:M18) -> 0.00020762235
E19: ='Daily Returns'!B19 -> 44477 | F19: =SUMPRODUCT($D$4:$M$4,'Daily Returns'!D19:M19) -> -0.009741014
E20: ='Daily Returns'!B20 -> 44480 | F20: =SUMPRODUCT($D$4:$M$4,'Daily Returns'!D20:M20) -> 0.02665423
E21: ='Daily Returns'!B21 -> 44481 | F21: =SUMPRODUCT($D$4:$M$4,'Daily Returns'!D21:M21) -> -0.0024008125
E22: ='Daily Returns'!B22 -> 44482 | F22: =SUMPRODUCT($D$4:$M$4,'Daily Returns'!D22:M22) -> 0.027267844
E23: ='Daily Returns'!B23 -> 44483 | F23: =SUMPRODUCT($D$4:$M$4,'Daily Returns'!D23:M23) -> 0.017761936
E24: ='Daily Returns'!B24 -> 44487 | F24: =SUMPRODUCT($D$4:$M$4,'Daily Returns'!D24:M24) -> 0.051246472
E25: ='Daily Returns'!B25 -> 44488 | F25: =SUMPRODUCT($D$4:$M$4,'Daily Returns'!D25:M25) -> -0.023597132
E26: ='Daily Returns'!B26 -> 44489 | F26: =SUMPRODUCT($D$4:$M$4,'Daily Returns'!D26:M26) -> -0.022098438
E27: ='Daily Returns'!B27 -> 44490 | F27: =SUMPRODUCT($D$4:$M$4,'Daily Returns'!D27:M27) -> 0.0034969673
E28: ='Daily Returns'!B28 -> 44491 | F28: =SUMPRODUCT($D$4:$M$4,'Daily Returns'!D28:M28) -> -0.0064509369
... E1242: ='Daily Returns'!B1242 -> 46281 | F1242: =SUMPRODUCT($D$4:$M$4,'Daily Returns'!D1242:M1242) -> -0.0015383151
E1244: Average Daily Return | F1244: =AVERAGE(F6:F1242) -> 0.0011028145
E1245: Annualised Return (compounded, 252 trading days) | F1245: =(1+F1244)^252-1 -> 0.32016421
E1246: Daily Std. Dev. | F1246: =STDEV(F6:F1242) -> 0.015490194
E1247: Annualised Std. Dev. | F1247: =F1246*SQRT(252) -> 0.2458992

Sheet Correlation Matrix
B2: Correlation Matrix - 10 Selected Companies (Monthly Returns)
B3: Computed with Excel CORREL across the 1,237 daily return observations (21-Sep-2021 to 16-Sep-2026) for each pair of companies, linked to the Daily Returns sheet.
C5: ADANIENSOL | D5: ADANIGREEN | E5: ADANIPOWER | F5: CESC | G5: JSWENERGY | H5: NHPC | I5: NTPC | J5: POWERGRID | K5: TATAPOWER | L5: TORNTPOWER
B6: ADANIENSOL | C6: =CORREL('Daily Returns'!D6:D1242,'Daily Returns'!D6:D1242) -> 1 | D6: =CORREL('Daily Returns'!D6:D1242,'Daily Returns'!E6:E1242) -> 0.7123365 | E6: =CORREL('Daily Returns'!D6:D1242,'Daily Returns'!F6:F1242) -> 0.55151203 | F6: =CORREL('Daily Returns'!D6:D1242,'Daily Returns'!G6:G1242) -> 0.26876095 | G6: =CORREL('Daily Returns'!D6:D1242,'Daily Returns'!H6:H1242) -> 0.28867672 | H6: =CORREL('Daily Returns'!D6:D1242,'Daily Returns'!I6:I1242) -> 0.27627533 | I6: =CORREL('Daily Returns'!D6:D1242,'Daily Returns'!J6:J1242) -> 0.32166574 | J6: =CORREL('Daily Returns'!D6:D1242,'Daily Returns'!K6:K1242) -> 0.26912385 | K6: =CORREL('Daily Returns'!D6:D1242,'Daily Returns'!L6:L1242) -> 0.3387659 | L6: =CORREL('Daily Returns'!D6:D1242,'Daily Returns'!M6:M1242) -> 0.24168163
B7: ADANIGREEN | C7: =CORREL('Daily Returns'!E6:E1242,'Daily Returns'!D6:D1242) -> 0.7123365 | D7: =CORREL('Daily Returns'!E6:E1242,'Daily Returns'!E6:E1242) -> 1 | E7: =CORREL('Daily Returns'!E6:E1242,'Daily Returns'!F6:F1242) -> 0.55704869 | F7: =CORREL('Daily Returns'!E6:E1242,'Daily Returns'!G6:G1242) -> 0.24969577 | G7: =CORREL('Daily Returns'!E6:E1242,'Daily Returns'!H6:H1242) -> 0.3108042 | H7: =CORREL('Daily Returns'!E6:E1242,'Daily Returns'!I6:I1242) -> 0.26648999 | I7: =CORREL('Daily Returns'!E6:E1242,'Daily Returns'!J6:J1242) -> 0.29384545 | J7: =CORREL('Daily Returns'!E6:E1242,'Daily Returns'!K6:K1242) -> 0.21641338 | K7: =CORREL('Daily Returns'!E6:E1242,'Daily Returns'!L6:L1242) -> 0.33080037 | L7: =CORREL('Daily Returns'!E6:E1242,'Daily Returns'!M6:M1242) -> 0.22226259
B8: ADANIPOWER | C8: =CORREL('Daily Returns'!F6:F1242,'Daily Returns'!D6:D1242) -> 0.55151203 | D8: =CORREL('Daily Returns'!F6:F1242,'Daily Returns'!E6:E1242) -> 0.55704869 | E8: =CORREL('Daily Returns'!F6:F1242,'Daily Returns'!F6:F1242) -> 1 | F8: =CORREL('Daily Returns'!F6:F1242,'Daily Returns'!G6:G1242) -> 0.29817998 | G8: =CORREL('Daily Returns'!F6:F1242,'Daily Returns'!H6:H1242) -> 0.37861597 | H8: =CORREL('Daily Returns'!F6:F1242,'Daily Returns'!I6:I1242) -> 0.30717777 | I8: =CORREL('Daily Returns'!F6:F1242,'Daily Returns'!J6:J1242) -> 0.36227624 | J8: =CORREL('Daily Returns'!F6:F1242,'Daily Returns'!K6:K1242) -> 0.249803 | K8: =CORREL('Daily Returns'!F6:F1242,'Daily Returns'!L6:L1242) -> 0.42779696 | L8: =CORREL('Daily Returns'!F6:F1242,'Daily Returns'!M6:M1242) -> 0.22148553
B9: CESC | C9: =CORREL('Daily Returns'!G6:G1242,'Daily Returns'!D6:D1242) -> 0.26876095 | D9: =CORREL('Daily Returns'!G6:G1242,'Daily Returns'!E6:E1242) -> 0.24969577 | E9: =CORREL('Daily Returns'!G6:G1242,'Daily Returns'!F6:F1242) -> 0.29817998 | F9: =CORREL('Daily Returns'!G6:G1242,'Daily Returns'!G6:G1242) -> 1 | G9: =CORREL('Daily Returns'!G6:G1242,'Daily Returns'!H6:H1242) -> 0.37432442 | H9: =CORREL('Daily Returns'!G6:G1242,'Daily Returns'!I6:I1242) -> 0.4366281 | I9: =CORREL('Daily Returns'!G6:G1242,'Daily Returns'!J6:J1242) -> 0.4564523 | J9: =CORREL('Daily Returns'!G6:G1242,'Daily Returns'!K6:K1242) -> 0.37084185 | K9: =CORREL('Daily Returns'!G6:G1242,'Daily Returns'!L6:L1242) -> 0.50082152 | L9: =CORREL('Daily Returns'!G6:G1242,'Daily Returns'!M6:M1242) -> 0.31852673
B10: JSWENERGY | C10: =CORREL('Daily Returns'!H6:H1242,'Daily Returns'!D6:D1242) -> 0.28867672 | D10: =CORREL('Daily Returns'!H6:H1242,'Daily Returns'!E6:E1242) -> 0.3108042 | E10: =CORREL('Daily Returns'!H6:H1242,'Daily Returns'!F6:F1242) -> 0.37861597 | F10: =CORREL('Daily Returns'!H6:H1242,'Daily Returns'!G6:G1242) -> 0.37432442 | G10: =CORREL('Daily Returns'!H6:H1242,'Daily Returns'!H6:H1242) -> 1 | H10: =CORREL('Daily Returns'!H6:H1242,'Daily Returns'!I6:I1242) -> 0.35236708 | I10: =CORREL('Daily Returns'!H6:H1242,'Daily Returns'!J6:J1242) -> 0.407494 | J10: =CORREL('Daily Returns'!H6:H1242,'Daily Returns'!K6:K1242) -> 0.35903812 | K10: =CORREL('Daily Returns'!H6:H1242,'Daily Returns'!L6:L1242) -> 0.47672422 | L10: =CORREL('Daily Returns'!H6:H1242,'Daily Returns'!M6:M1242) -> 0.32839048
B11: NHPC | C11: =CORREL('Daily Returns'!I6:I1242,'Daily Returns'!D6:D1242) -> 0.27627533 | D11: =CORREL('Daily Returns'!I6:I1242,'Daily Returns'!E6:E1242) -> 0.26648999 | E11: =CORREL('Daily Returns'!I6:I1242,'Daily Returns'!F6:F1242) -> 0.30717777 | F11: =CORREL('Daily Returns'!I6:I1242,'Daily Returns'!G6:G1242) -> 0.4366281 | G11: =CORREL('Daily Returns'!I6:I1242,'Daily Returns'!H6:H1242) -> 0.35236708 | H11: =CORREL('Daily Returns'!I6:I1242,'Daily Returns'!I6:I1242) -> 1 | I11: =CORREL('Daily Returns'!I6:I1242,'Daily Returns'!J6:J1242) -> 0.42330181 | J11: =CORREL('Daily Returns'!I6:I1242,'Daily Returns'!K6:K1242) -> 0.36172284 | K11: =CORREL('Daily Returns'!I6:I1242,'Daily Returns'!L6:L1242) -> 0.49198183 | L11: =CORREL('Daily Returns'!I6:I1242,'Daily Returns'!M6:M1242) -> 0.31579502
B12: NTPC | C12: =CORREL('Daily Returns'!J6:J1242,'Daily Returns'!D6:D1242) -> 0.32166574 | D12: =CORREL('Daily Returns'!J6:J1242,'Daily Returns'!E6:E1242) -> 0.29384545 | E12: =CORREL('Daily Returns'!J6:J1242,'Daily Returns'!F6:F1242) -> 0.36227624 | F12: =CORREL('Daily Returns'!J6:J1242,'Daily Returns'!G6:G1242) -> 0.4564523 | G12: =CORREL('Daily Returns'!J6:J1242,'Daily Returns'!H6:H1242) -> 0.407494 | H12: =CORREL('Daily Returns'!J6:J1242,'Daily Returns'!I6:I1242) -> 0.42330181 | I12: =CORREL('Daily Returns'!J6:J1242,'Daily Returns'!J6:J1242) -> 1 | J12: =CORREL('Daily Returns'!J6:J1242,'Daily Returns'!K6:K1242) -> 0.59614378 | K12: =CORREL('Daily Returns'!J6:J1242,'Daily Returns'!L6:L1242) -> 0.55505059 | L12: =CORREL('Daily Returns'!J6:J1242,'Daily Returns'!M6:M1242) -> 0.39430667
B13: POWERGRID | C13: =CORREL('Daily Returns'!K6:K1242,'Daily Returns'!D6:D1242) -> 0.26912385 | D13: =CORREL('Daily Returns'!K6:K1242,'Daily Returns'!E6:E1242) -> 0.21641338 | E13: =CORREL('Daily Returns'!K6:K1242,'Daily Returns'!F6:F1242) -> 0.249803 | F13: =CORREL('Daily Returns'!K6:K1242,'Daily Returns'!G6:G1242) -> 0.37084185 | G13: =CORREL('Daily Returns'!K6:K1242,'Daily Returns'!H6:H1242) -> 0.35903812 | H13: =CORREL('Daily Returns'!K6:K1242,'Daily Returns'!I6:I1242) -> 0.36172284 | I13: =CORREL('Daily Returns'!K6:K1242,'Daily Returns'!J6:J1242) -> 0.59614378 | J13: =CORREL('Daily Returns'!K6:K1242,'Daily Returns'!K6:K1242) -> 1 | K13: =CORREL('Daily Returns'!K6:K1242,'Daily Returns'!L6:L1242) -> 0.45187652 | L13: =CORREL('Daily Returns'!K6:K1242,'Daily Returns'!M6:M1242) -> 0.30577951
B14: TATAPOWER | C14: =CORREL('Daily Returns'!L6:L1242,'Daily Returns'!D6:D1242) -> 0.3387659 | D14: =CORREL('Daily Returns'!L6:L1242,'Daily Returns'!E6:E1242) -> 0.33080037 | E14: =CORREL('Daily Returns'!L6:L1242,'Daily Returns'!F6:F1242) -> 0.42779696 | F14: =CORREL('Daily Returns'!L6:L1242,'Daily Returns'!G6:G1242) -> 0.50082152 | G14: =CORREL('Daily Returns'!L6:L1242,'Daily Returns'!H6:H1242) -> 0.47672422 | H14: =CORREL('Daily Returns'!L6:L1242,'Daily Returns'!I6:I1242) -> 0.49198183 | I14: =CORREL('Daily Returns'!L6:L1242,'Daily Returns'!J6:J1242) -> 0.55505059 | J14: =CORREL('Daily Returns'!L6:L1242,'Daily Returns'!K6:K1242) -> 0.45187652 | K14: =CORREL('Daily Returns'!L6:L1242,'Daily Returns'!L6:L1242) -> 1 | L14: =CORREL('Daily Returns'!L6:L1242,'Daily Returns'!M6:M1242) -> 0.4439229
B15: TORNTPOWER | C15: =CORREL('Daily Returns'!M6:M1242,'Daily Returns'!D6:D1242) -> 0.24168163 | D15: =CORREL('Daily Returns'!M6:M1242,'Daily Returns'!E6:E1242) -> 0.22226259 | E15: =CORREL('Daily Returns'!M6:M1242,'Daily Returns'!F6:F1242) -> 0.22148553 | F15: =CORREL('Daily Returns'!M6:M1242,'Daily Returns'!G6:G1242) -> 0.31852673 | G15: =CORREL('Daily Returns'!M6:M1242,'Daily Returns'!H6:H1242) -> 0.32839048 | H15: =CORREL('Daily Returns'!M6:M1242,'Daily Returns'!I6:I1242) -> 0.31579502 | I15: =CORREL('Daily Returns'!M6:M1242,'Daily Returns'!J6:J1242) -> 0.39430667 | J15: =CORREL('Daily Returns'!M6:M1242,'Daily Returns'!K6:K1242) -> 0.30577951 | K15: =CORREL('Daily Returns'!M6:M1242,'Daily Returns'!L6:L1242) -> 0.4439229 | L15: =CORREL('Daily Returns'!M6:M1242,'Daily Returns'!M6:M1242) -> 1

Sheet Covariance Matrix
B2: Covariance Matrix - 10 Selected Companies (Monthly Returns)
B3: Computed with Excel COVAR across the 1,237 daily return observations (21-Sep-2021 to 16-Sep-2026) for each pair of companies, linked to the Daily Returns sheet.
C5: ADANIENSOL | D5: ADANIGREEN | E5: ADANIPOWER | F5: CESC | G5: JSWENERGY | H5: NHPC | I5: NTPC | J5: POWERGRID | K5: TATAPOWER | L5: TORNTPOWER
B6: ADANIENSOL | C6: =COVAR('Daily Returns'!D6:D1242,'Daily Returns'!D6:D1242) -> 0.0010064446 | D6: =COVAR('Daily Returns'!D6:D1242,'Daily Returns'!E6:E1242) -> 0.00073847232 | E6: =COVAR('Daily Returns'!D6:D1242,'Daily Returns'!F6:F1242) -> 0.00054189114 | F6: =COVAR('Daily Returns'!D6:D1242,'Daily Returns'!G6:G1242) -> 0.00017403346 | G6: =COVAR('Daily Returns'!D6:D1242,'Daily Returns'!H6:H1242) -> 0.00024284038 | H6: =COVAR('Daily Returns'!D6:D1242,'Daily Returns'!I6:I1242) -> 0.00018853735 | I6: =COVAR('Daily Returns'!D6:D1242,'Daily Returns'!J6:J1242) -> 0.00016084264 | J6: =COVAR('Daily Returns'!D6:D1242,'Daily Returns'!K6:K1242) -> 0.00013554785 | K6: =COVAR('Daily Returns'!D6:D1242,'Daily Returns'!L6:L1242) -> 0.00021912302 | L6: =COVAR('Daily Returns'!D6:D1242,'Daily Returns'!M6:M1242) -> 0.00017374417
B7: ADANIGREEN | C7: =COVAR('Daily Returns'!E6:E1242,'Daily Returns'!D6:D1242) -> 0.00073847232 | D7: =COVAR('Daily Returns'!E6:E1242,'Daily Returns'!E6:E1242) -> 0.0010678448 | E7: =COVAR('Daily Returns'!E6:E1242,'Daily Returns'!F6:F1242) -> 0.00056377959 | F7: =COVAR('Daily Returns'!E6:E1242,'Daily Returns'!G6:G1242) -> 0.00016654703 | G7: =COVAR('Daily Returns'!E6:E1242,'Daily Returns'!H6:H1242) -> 0.00026931165 | H7: =COVAR('Daily Returns'!E6:E1242,'Daily Returns'!I6:I1242) -> 0.00018732482 | I7: =COVAR('Daily Returns'!E6:E1242,'Daily Returns'!J6:J1242) -> 0.00015134724 | J7: =COVAR('Daily Returns'!E6:E1242,'Daily Returns'!K6:K1242) -> 0.00011227516 | K7: =COVAR('Daily Returns'!E6:E1242,'Daily Returns'!L6:L1242) -> 0.00022040093 | L7: =COVAR('Daily Returns'!E6:E1242,'Daily Returns'!M6:M1242) -> 0.0001645857
B8: ADANIPOWER | C8: =COVAR('Daily Returns'!F6:F1242,'Daily Returns'!D6:D1242) -> 0.00054189114 | D8: =COVAR('Daily Returns'!F6:F1242,'Daily Returns'!E6:E1242) -> 0.00056377959 | E8: =COVAR('Daily Returns'!F6:F1242,'Daily Returns'!F6:F1242) -> 0.00095923329 | F8: =COVAR('Daily Returns'!F6:F1242,'Daily Returns'!G6:G1242) -> 0.00018850039 | G8: =COVAR('Daily Returns'!F6:F1242,'Daily Returns'!H6:H1242) -> 0.00031093902 | H8: =COVAR('Daily Returns'!F6:F1242,'Daily Returns'!I6:I1242) -> 0.00020465024 | I8: =COVAR('Daily Returns'!F6:F1242,'Daily Returns'!J6:J1242) -> 0.00017684933 | J8: =COVAR('Daily Returns'!F6:F1242,'Daily Returns'!K6:K1242) -> 0.00012283023 | K8: =COVAR('Daily Returns'!F6:F1242,'Daily Returns'!L6:L1242) -> 0.00027014267 | L8: =COVAR('Daily Returns'!F6:F1242,'Daily Returns'!M6:M1242) -> 0.00015544585
B9: CESC | C9: =COVAR('Daily Returns'!G6:G1242,'Daily Returns'!D6:D1242) -> 0.00017403346 | D9: =COVAR('Daily Returns'!G6:G1242,'Daily Returns'!E6:E1242) -> 0.00016654703 | E9: =COVAR('Daily Returns'!G6:G1242,'Daily Returns'!F6:F1242) -> 0.00018850039 | F9: =COVAR('Daily Returns'!G6:G1242,'Daily Returns'!G6:G1242) -> 0.00041662304 | G9: =COVAR('Daily Returns'!G6:G1242,'Daily Returns'!H6:H1242) -> 0.00020259745 | H9: =COVAR('Daily Returns'!G6:G1242,'Daily Returns'!I6:I1242) -> 0.00019170952 | I9: =COVAR('Daily Returns'!G6:G1242,'Daily Returns'!J6:J1242) -> 0.00014684815 | J9: =COVAR('Daily Returns'!G6:G1242,'Daily Returns'!K6:K1242) -> 0.00012017271 | K9: =COVAR('Daily Returns'!G6:G1242,'Daily Returns'!L6:L1242) -> 0.00020842412 | L9: =COVAR('Daily Returns'!G6:G1242,'Daily Returns'!M6:M1242) -> 0.00014732932
B10: JSWENERGY | C10: =COVAR('Daily Returns'!H6:H1242,'Daily Returns'!D6:D1242) -> 0.00024284038 | D10: =COVAR('Daily Returns'!H6:H1242,'Daily Returns'!E6:E1242) -> 0.00026931165 | E10: =COVAR('Daily Returns'!H6:H1242,'Daily Returns'!F6:F1242) -> 0.00031093902 | F10: =COVAR('Daily Returns'!H6:H1242,'Daily Returns'!G6:G1242) -> 0.00020259745 | G10: =COVAR('Daily Returns'!H6:H1242,'Daily Returns'!H6:H1242) -> 0.00070311825 | H10: =COVAR('Daily Returns'!H6:H1242,'Daily Returns'!I6:I1242) -> 0.00020098788 | I10: =COVAR('Daily Returns'!H6:H1242,'Daily Returns'!J6:J1242) -> 0.0001703087 | J10: =COVAR('Daily Returns'!H6:H1242,'Daily Returns'!K6:K1242) -> 0.00015114725 | K10: =COVAR('Daily Returns'!H6:H1242,'Daily Returns'!L6:L1242) -> 0.00025773581 | L10: =COVAR('Daily Returns'!H6:H1242,'Daily Returns'!M6:M1242) -> 0.0001973224
B11: NHPC | C11: =COVAR('Daily Returns'!I6:I1242,'Daily Returns'!D6:D1242) -> 0.00018853735 | D11: =COVAR('Daily Returns'!I6:I1242,'Daily Returns'!E6:E1242) -> 0.00018732482 | E11: =COVAR('Daily Returns'!I6:I1242,'Daily Returns'!F6:F1242) -> 0.00020465024 | F11: =COVAR('Daily Returns'!I6:I1242,'Daily Returns'!G6:G1242) -> 0.00019170952 | G11: =COVAR('Daily Returns'!I6:I1242,'Daily Returns'!H6:H1242) -> 0.00020098788 | H11: =COVAR('Daily Returns'!I6:I1242,'Daily Returns'!I6:I1242) -> 0.00046272259 | I11: =COVAR('Daily Returns'!I6:I1242,'Daily Returns'!J6:J1242) -> 0.00014351983 | J11: =COVAR('Daily Returns'!I6:I1242,'Daily Returns'!K6:K1242) -> 0.00012353265 | K11: =COVAR('Daily Returns'!I6:I1242,'Daily Returns'!L6:L1242) -> 0.00021577582 | L11: =COVAR('Daily Returns'!I6:I1242,'Daily Returns'!M6:M1242) -> 0.00015393496
B12: NTPC | C12: =COVAR('Daily Returns'!J6:J1242,'Daily Returns'!D6:D1242) -> 0.00016084264 | D12: =COVAR('Daily Returns'!J6:J1242,'Daily Returns'!E6:E1242) -> 0.00015134724 | E12: =COVAR('Daily Returns'!J6:J1242,'Daily Returns'!F6:F1242) -> 0.00017684933 | F12: =COVAR('Daily Returns'!J6:J1242,'Daily Returns'!G6:G1242) -> 0.00014684815 | G12: =COVAR('Daily Returns'!J6:J1242,'Daily Returns'!H6:H1242) -> 0.0001703087 | H12: =COVAR('Daily Returns'!J6:J1242,'Daily Returns'!I6:I1242) -> 0.00014351983 | I12: =COVAR('Daily Returns'!J6:J1242,'Daily Returns'!J6:J1242) -> 0.00024842934 | J12: =COVAR('Daily Returns'!J6:J1242,'Daily Returns'!K6:K1242) -> 0.00014917565 | K12: =COVAR('Daily Returns'!J6:J1242,'Daily Returns'!L6:L1242) -> 0.00017837228 | L12: =COVAR('Daily Returns'!J6:J1242,'Daily Returns'!M6:M1242) -> 0.0001408339
B13: POWERGRID | C13: =COVAR('Daily Returns'!K6:K1242,'Daily Returns'!D6:D1242) -> 0.00013554785 | D13: =COVAR('Daily Returns'!K6:K1242,'Daily Returns'!E6:E1242) -> 0.00011227516 | E13: =COVAR('Daily Returns'!K6:K1242,'Daily Returns'!F6:F1242) -> 0.00012283023 | F13: =COVAR('Daily Returns'!K6:K1242,'Daily Returns'!G6:G1242) -> 0.00012017271 | G13: =COVAR('Daily Returns'!K6:K1242,'Daily Returns'!H6:H1242) -> 0.00015114725 | H13: =COVAR('Daily Returns'!K6:K1242,'Daily Returns'!I6:I1242) -> 0.00012353265 | I13: =COVAR('Daily Returns'!K6:K1242,'Daily Returns'!J6:J1242) -> 0.00014917565 | J13: =COVAR('Daily Returns'!K6:K1242,'Daily Returns'!K6:K1242) -> 0.00025205249 | K13: =COVAR('Daily Returns'!K6:K1242,'Daily Returns'!L6:L1242) -> 0.00014627114 | L13: =COVAR('Daily Returns'!K6:K1242,'Daily Returns'!M6:M1242) -> 0.00011000832
B14: TATAPOWER | C14: =COVAR('Daily Returns'!L6:L1242,'Daily Returns'!D6:D1242) -> 0.00021912302 | D14: =COVAR('Daily Returns'!L6:L1242,'Daily Returns'!E6:E1242) -> 0.00022040093 | E14: =COVAR('Daily Returns'!L6:L1242,'Daily Returns'!F6:F1242) -> 0.00027014267 | F14: =COVAR('Daily Returns'!L6:L1242,'Daily Returns'!G6:G1242) -> 0.00020842412 | G14: =COVAR('Daily Returns'!L6:L1242,'Daily Returns'!H6:H1242) -> 0.00025773581 | H14: =COVAR('Daily Returns'!L6:L1242,'Daily Returns'!I6:I1242) -> 0.00021577582 | I14: =COVAR('Daily Returns'!L6:L1242,'Daily Returns'!J6:J1242) -> 0.00017837228 | J14: =COVAR('Daily Returns'!L6:L1242,'Daily Returns'!K6:K1242) -> 0.00014627114 | K14: =COVAR('Daily Returns'!L6:L1242,'Daily Returns'!L6:L1242) -> 0.00041570641 | L14: =COVAR('Daily Returns'!L6:L1242,'Daily Returns'!M6:M1242) -> 0.00020510326
B15: TORNTPOWER | C15: =COVAR('Daily Returns'!M6:M1242,'Daily Returns'!D6:D1242) -> 0.00017374417 | D15: =COVAR('Daily Returns'!M6:M1242,'Daily Returns'!E6:E1242) -> 0.0001645857 | E15: =COVAR('Daily Returns'!M6:M1242,'Daily Returns'!F6:F1242) -> 0.00015544585 | F15: =COVAR('Daily Returns'!M6:M1242,'Daily Returns'!G6:G1242) -> 0.00014732932 | G15: =COVAR('Daily Returns'!M6:M1242,'Daily Returns'!H6:H1242) -> 0.0001973224 | H15: =COVAR('Daily Returns'!M6:M1242,'Daily Returns'!I6:I1242) -> 0.00015393496 | I15: =COVAR('Daily Returns'!M6:M1242,'Daily Returns'!J6:J1242) -> 0.0001408339 | J15: =COVAR('Daily Returns'!M6:M1242,'Daily Returns'!K6:K1242) -> 0.00011000832 | K15: =COVAR('Daily Returns'!M6:M1242,'Daily Returns'!L6:L1242) -> 0.00020510326 | L15: =COVAR('Daily Returns'!M6:M1242,'Daily Returns'!M6:M1242) -> 0.00051350337

Sheet Markowitz Optimisation
B2: Portfolio 3: Efficient Markowitz Portfolio
B3: Objective: maximise the Sharpe ratio, subject to weights summing to 100%, no short-selling (weights >= 0) and no borrowing (weights <= 1). Solved using Python/SciPy SLSQP on the 1,237-day covariance matrix and mean daily returns - mathematically equivalent to Excel Solver's GRG Nonlinear engine on the same objective and constraints. NOT run inside Excel Solver itself; open Data > Solver with the objective/constraint cells below to verify or re-optimise for the viva.
B6: Solver Setup (replicate this in Excel Data > Solver)
B7: Objective cell | C7: F1273 (Sharpe ratio) - Set to: Max
B8: By changing variable cells | C8: C16:C25 (portfolio weights)
B9: Constraint 1 | C9: C26 = 1
B10: Constraint 2 | C10: C16:C25 >= 0 (no short-selling)
B11: Constraint 3 | C11: C16:C25 <= 1 (no borrowing / leverage)
B12: Solving method | C12: GRG Nonlinear
B15: Company | C15: Optimal Weight
B16: Adani Energy Solutions | C16: 0
B17: Adani Green | C17: 0
B18: Adani Power | C18: 0.3756
B19: CESC | C19: 0
B20: JSW Energy | C20: 0
B21: NHPC | C21: 0.1225
B22: NTPC | C22: 0.2282
B23: Power Grid | C23: 0.1287
B24: Tata Power | C24: 0
B25: Torrent Power | C25: 0.1451
B26: TOTAL | C26: =SUM(C16:C25) -> 1.0001
B28: (helper row - weights mirrored horizontally) | D28: =C16 -> 0 | E28: =C17 -> 0 | F28: =C18 -> 0.3756 | G28: =C19 -> 0 | H28: =C20 -> 0 | I28: =C21 -> 0.1225 | J28: =C22 -> 0.2282 | K28: =C23 -> 0.1287 | L28: =C24 -> 0 | M28: =C25 -> 0.1451
E29: Date | F29: Portfolio Daily Return
E30: ='Daily Returns'!B6 -> 44460 | F30: =SUMPRODUCT($D$28:$M$28,'Daily Returns'!D6:M6) -> -0.0019823817
E31: ='Daily Returns'!B7 -> 44461 | F31: =SUMPRODUCT($D$28:$M$28,'Daily Returns'!D7:M7) -> 0.0064433329
E32: ='Daily Returns'!B8 -> 44462 | F32: =SUMPRODUCT($D$28:$M$28,'Daily Returns'!D8:M8) -> 0.011564987
E33: ='Daily Returns'!B9 -> 44463 | F33: =SUMPRODUCT($D$28:$M$28,'Daily Returns'!D9:M9) -> -0.0078072749
E34: ='Daily Returns'!B10 -> 44466 | F34: =SUMPRODUCT($D$28:$M$28,'Daily Returns'!D10:M10) -> 0.0072331229
E35: ='Daily Returns'!B11 -> 44467 | F35: =SUMPRODUCT($D$28:$M$28,'Daily Returns'!D11:M11) -> 0.015992174
E36: ='Daily Returns'!B12 -> 44468 | F36: =SUMPRODUCT($D$28:$M$28,'Daily Returns'!D12:M12) -> 0.03993115
E37: ='Daily Returns'!B13 -> 44469 | F37: =SUMPRODUCT($D$28:$M$28,'Daily Returns'!D13:M13) -> -0.0069260677
E38: ='Daily Returns'!B14 -> 44470 | F38: =SUMPRODUCT($D$28:$M$28,'Daily Returns'!D14:M14) -> -0.006522254
E39: ='Daily Returns'!B15 -> 44473 | F39: =SUMPRODUCT($D$28:$M$28,'Daily Returns'!D15:M15) -> 0.030550958
E40: ='Daily Returns'!B16 -> 44474 | F40: =SUMPRODUCT($D$28:$M$28,'Daily Returns'!D16:M16) -> 0.021430346
E41: ='Daily Returns'!B17 -> 44475 | F41: =SUMPRODUCT($D$28:$M$28,'Daily Returns'!D17:M17) -> -0.024396841
... E95: ='Daily Returns'!B71 -> 44554 | F95: =SUMPRODUCT($D$28:$M$28,'Daily Returns'!D71:M71) -> -0.014862539
B96: Efficient Frontier (illustrative, 6 points) | E96: ='Daily Returns'!B72 -> 44557 | F96: =SUMPRODUCT($D$28:$M$28,'Daily Returns'!D72:M72) -> 0.0046542345
B97: Target Ann. Return | C97: Ann. Std Dev (Risk) | E97: ='Daily Returns'!B73 -> 44558 | F97: =SUMPRODUCT($D$28:$M$28,'Daily Returns'!D73:M73) -> 0.015095025
B98: 0.24377825 | C98: 0.21123595 | E98: ='Daily Returns'!B74 -> 44559 | F98: =SUMPRODUCT($D$28:$M$28,'Daily Returns'!D74:M74) -> -0.0087189721
B99: 0.33095328 | C99: 0.22957764 | E99: ='Daily Returns'!B75 -> 44560 | F99: =SUMPRODUCT($D$28:$M$28,'Daily Returns'!D75:M75) -> 0.010500327
...

Sheet Portfolio 4 - Benchmark
B2: Portfolio 4: Benchmark Portfolio
B3: Uses the benchmark daily return series from the Daily Returns sheet, labelled 'Nifty Power (Energy)'. FLAGGED: this series' price level matches the Nifty Energy Index, not the Nifty Power Index that the 10 selected companies more closely track - confirm the allocated benchmark before final submission (see Data Sources & Assumptions).
B5: Date | C5: Benchmark Daily Return
B6: ='Daily Returns'!B6 -> 44460 | C6: ='Daily Returns'!C6 -> 0.0052348864
B7: ='Daily Returns'!B7 -> 44461 | C7: ='Daily Returns'!C7 -> 0.0081947994
B8: ='Daily Returns'!B8 -> 44462 | C8: ='Daily Returns'!C8 -> 0.018326221
B9: ='Daily Returns'!B9 -> 44463 | C9: ='Daily Returns'!C9 -> -0.0080755484
B10: ='Daily Returns'!B10 -> 44466 | C10: ='Daily Returns'!C10 -> 0.013335513
B11: ='Daily Returns'!B11 -> 44467 | C11: ='Daily Returns'!C11 -> 0.02014446
B12: ='Daily Returns'!B12 -> 44468 | C12: ='Daily Returns'!C12 -> 0.018494968
B13: ='Daily Returns'!B13 -> 44469 | C13: ='Daily Returns'!C13 -> -0.00026241496
B14: ='Daily Returns'!B14 -> 44470 | C14: ='Daily Returns'!C14 -> 0.006196806
B15: ='Daily Returns'!B15 -> 44473 | C15: ='Daily Returns'!C15 -> 0.014539004
B16: ='Daily Returns'!B16 -> 44474 | C16: ='Daily Returns'!C16 -> 0.028779152
B17: ='Daily Returns'!B17 -> 44475 | C17: ='Daily Returns'!C17 -> -0.0045050956
... B1242: ='Daily Returns'!B1242 -> 46281 | C1242: ='Daily Returns'!C1242 -> 0.00095429223
B1244: Average Daily Return | C1244: =AVERAGE(C6:C1242) -> 0.00053116448
B1245: Annualised Return (compounded, 252 days) | C1245: =(1+C1244)^252-1 -> 0.14318464
B1246: Daily Std. Dev. | C1246: =STDEV(C6:C1242) -> 0.012390123
B1247: Annualised Std. Dev. | C1247: =C1246*SQRT(252) -> 0.1966871

Sheet Portfolio 5 - Mutual Fund 1
B2: Portfolio 5: Comparable Mutual Fund Scheme 1
B3: Selected because it is one of the longest-running (since 2004) power & infrastructure sectoral funds in India, giving a genuine 5-year track record comparable to the analysis period, and its top holdings overlap materially with the 10 selected companies (NTPC, Tata Power).
B5: Scheme name | C5: Nippon India Power & Infra Fund - Growth
B6: Fund house | C6: Nippon India Mutual Fund
B7: Investment objective | C7: Long-term capital appreciation by investing in power and allied infrastructure sector companies
B8: Launch date | C8: 08-May-2004
B9: AUM (Rs Cr, approx.) | C9: 8043 | D9: share.market, Jul-2026
B10: Top holdings | C10: Reliance Industries, NTPC, Bharti Airtel, L&T, Tata Power | D10: share.market, Jul-2026
B11: 5-Year CAGR | C11: 0.2263 | D11: share.market, Jul-2026
B12: 1-Year Return
B14: THIRD-PARTY RISK METRICS (not computed on the same daily/5-yr basis as Portfolios 1-4)
B15: Annualised Std. Dev. (3-yr, provider-computed) | C15: 0.1787
B16: Beta (3-yr, vs provider benchmark) | C16: 1.03
B17: Sharpe Ratio (3-yr, provider-computed) | C17: 1.13
B18: Alpha (3-yr, provider-computed) | C18: 0.0331
B19: Treynor Ratio (our 5-yr CAGR & Rf, provider's beta - mixed-source) | C19: =(C11-0.053)/C16 -> 0.16825243
B20: Source: advisorkhoj.com, Nippon India Power & Infra Fund - Growth Plan, retrieved Sep-2026. These figures use the provider's own methodology (typically 3-year, monthly-return basis and their own risk-free assumption) - NOT the same 5-year daily-return, 91-day-T-Bill basis used for Portfolios 1-4. Shown to satisfy the Dashboard's completeness requirement, but not strictly like-for-like comparable to the other four portfolios. A fully consistent comparison would require downloading this fund's actual daily/monthly NAV history.

Sheet Portfolio 6 - Mutual Fund 2
B2: Portfolio 6: Comparable Mutual Fund Scheme 2
B3: Selected as a second comparable scheme with meaningful power-sector exposure (Adani Power and Adani Energy Solutions are top-10 holdings), though its mandate is broader (Resources & Energy, including cement, steel and metals) than a pure power play - a disclosed limitation, not full sector overlap with the benchmark.
B5: Scheme name | C5: Tata Resources & Energy Fund - Growth
B6: Fund house | C6: Tata Mutual Fund
B7: Investment objective | C7: Long-term capital appreciation by investing at least 80% of net assets in equity/equity-related instruments of Resources & Energy sector companies
B8: Launch date | C8: 04-Dec-2015
B9: AUM (Rs Cr, approx.) | C9: 1361 | D9: share.market, Jul-2026
B10: Top holdings | C10: UltraTech Cement, Ambuja Cements, Tata Steel, Adani Power, Adani Energy Solutions | D10: share.market, Jul-2026
B11: 5-Year CAGR | C11: 0.13 | D11: share.market, Jul-2026
B12: Expense Ratio | C12: 0.0212 | D12: equiruswealth.com, Jan-2026
B14: THIRD-PARTY RISK METRICS (not computed on the same daily/5-yr basis as Portfolios 1-4)
B15: Annualised Std. Dev. (3-yr, provider-computed) | C15: 0.1721
B16: Beta (3-yr, vs provider benchmark) | C16: 0.84
B17: Sharpe Ratio (3-yr, provider-computed) | C17: 0.28
B18: Alpha (3-yr, provider-computed) | C18: -0.0051
B19: Treynor Ratio (our 5-yr CAGR & Rf, provider's beta - mixed-source) | C19: =(C11-0.053)/C16 -> 0.091666667
B20: Source: advisorkhoj.com, Tata Resources & Energy Fund - Regular Plan Growth, retrieved Sep-2026. These figures use the provider's own methodology (typically 3-year, monthly-return basis and their own risk-free assumption) - NOT the same 5-year daily-return, 91-day-T-Bill basis used for Portfolios 1-4. Shown to satisfy the Dashboard's completeness requirement, but not strictly like-for-like comparable to the other four portfolios. A fully consistent comparison would require downloading this fund's actual daily/monthly NAV history.

Sheet Portfolio Performance
B2: Comparative Performance - All Six Portfolios
B3: Beta = COVAR(portfolio returns, benchmark returns) / VAR(benchmark returns), computed on DAILY returns (1,237 observations). Sharpe = (Ann. Return - Rf) / Ann. Std Dev. Treynor = (Ann. Return - Rf) / Beta. Jensen Alpha = Actual Return - [Rf + Beta x (Benchmark Return - Rf)]. Risk-free rate = 5.30% p.a. (91-day T-Bill, Aug-2026). Annualisation: (1+avg daily return)^252 - 1 for return; daily SD x SQRT(252) for risk. Portfolios 5 and 6 (mutual funds) show only the reported 5-year CAGR - no daily NAV series was available for them.
B5: Portfolio | C5: Ann. Return (CAGR proxy) | D5: Ann. Std Dev (Risk) | E5: Beta | F5: Sharpe Ratio | G5: Treynor Ratio | H5: Jensen's Alpha
B6: 1. Equal Weighted | C6: ='Portfolio 1 - Equal Weight'!F1245 -> 0.28753819 | D6: ='Portfolio 1 - Equal Weight'!F1247 -> 0.25033414 | E6: =COVAR('Portfolio 1 - Equal Weight'!F6:F1242,'Portfolio 4 - Benchmark'!C6:C1242)/VAR('Portfolio 4 - Benchmark'!C6:C1242) -> 0.42812329 | F6: =(C6-0.053)/D6 -> 0.93690056 | G6: =(C6-0.053)/E6 -> 0.54782861 | H6: =C6-(0.053+E6*('Portfolio 4 - Benchmark'!C1245-0.053)) -> 0.19592805
B7: 2. Criteria-Based (Composite Score) | C7: ='Portfolio 2 - Criteria Based'!F1245 -> 0.32016421 | D7: ='Portfolio 2 - Criteria Based'!F1247 -> 0.2458992 | E7: =COVAR('Portfolio 2 - Criteria Based'!F6:F1242,'Portfolio 4 - Benchmark'!C6:C1242)/VAR('Portfolio 4 - Benchmark'!C6:C1242) -> 0.40968806 | F7: =(C7-0.053)/D7 -> 1.0864786 | G7: =(C7-0.053)/E7 -> 0.65211617 | H7: =C7-(0.053+E7*('Portfolio 4 - Benchmark'!C1245-0.053)) -> 0.23021664
B8: 3. Markowitz (Max Sharpe) | C8: ='Markowitz Optimisation'!F1270 -> 0.47914949 | D8: ='Markowitz Optimisation'!F1272 -> 0.26939008 | E8: =COVAR('Markowitz Optimisation'!F30:F1266,'Portfolio 4 - Benchmark'!C6:C1242)/VAR('Portfolio 4 - Benchmark'!C6:C1242) -> 0.39150566 | F8: =(C8-0.053)/D8 -> 1.5819049 | G8: =(C8-0.053)/E8 -> 1.0884887 | H8: =C8-(0.053+E8*('Portfolio 4 - Benchmark'!C1245-0.053)) -> 0.39084169
B9: 4. Benchmark (Nifty Power/Energy - flagged) | C9: ='Portfolio 4 - Benchmark'!C1245 -> 0.14318464 | D9: ='Portfolio 4 - Benchmark'!C1247 -> 0.1966871 | E9: =COVAR('Portfolio 4 - Benchmark'!C6:C1242,'Portfolio 4 - Benchmark'!C6:C1242)/VAR('Portfolio 4 - Benchmark'!C6:C1242) -> 0.99919159 | F9: =(C9-0.053)/D9 -> 0.45851833 | G9: =(C9-0.053)/E9 -> 0.090257605 | H9: =C9-(0.053+E9*('Portfolio 4 - Benchmark'!C1245-0.053)) -> 7.2905934e-05
B10: 5. Mutual Fund 1 - Nippon India Power & Infra | C10: ='Portfolio 5 - Mutual Fund 1'!C11 -> 0.2263 | D10: ='Portfolio 5 - Mutual Fund 1'!C15 -> 0.1787 | E10: ='Portfolio 5 - Mutual Fund 1'!C16 -> 1.03 | F10: ='Portfolio 5 - Mutual Fund 1'!C17 -> 1.13 | G10: ='Portfolio 5 - Mutual Fund 1'!C19 -> 0.16825243 | H10: ='Portfolio 5 - Mutual Fund 1'!C18 -> 0.0331
B11: 6. Mutual Fund 2 - Tata Resources & Energy | C11: ='Portfolio 6 - Mutual Fund 2'!C11 -> 0.13 | D11: ='Portfolio 6 - Mutual Fund 2'!C15 -> 0.1721 | E11: ='Portfolio 6 - Mutual Fund 2'!C16 -> 0.84 | F11: ='Portfolio 6 - Mutual Fund 2'!C17 -> 0.28 | G11: ='Portfolio 6 - Mutual Fund 2'!C19 -> 0.091666667 | H11: ='Portfolio 6 - Mutual Fund 2'!C18 -> -0.0051

Sheet Returns & Ratios
B2: Return-wise Calculation (Daily Basis): Periodic Returns -> Cumulative Return -> CAGR -> Risk-Adjusted Ratios
B3: Self-contained sheet: pulls each portfolio's DAILY return from its own sheet, builds a Rs 100 cumulative value index day by day (1,237 trading days, 21-Sep-2021 to 16-Sep-2026), then derives Cumulative Return, CAGR, Annualised Return, Annualised Risk, Beta, Sharpe, Treynor and Jensen's Alpha from that index and return series.
B5: A. Daily Returns and Cumulative Value Index (Rs 100 base)
